Workbook

Sheet 사용안내
A1: 마인드 근태 · 연차 관리대장
A2: 취업규칙 제11조(출근 및 퇴근) · 제22조(연차유급휴가) 운영용
A5: 시트 구성
A6: 직원명부 | B6: 가장 먼저 채웁니다. 사번·성명·입사일을 넣으면 나머지 시트가 이 값을 자동으로 끌어옵니다.
A7: 연차현황 | B7: 입사일만 있으면 발생·사용·잔여 일수가 전부 자동 계산됩니다. 입력할 곳은 「이월」 칸뿐입니다.
A8: 휴가대장 | B8: 휴가를 쓸 때마다 한 줄씩 기록합니다. 이 기록이 연차현황의 「사용」 일수가 됩니다.
A9: 근태기록 | B9: 출근·퇴근 시각을 매일 기록합니다. 근무시간과 연장시간은 자동으로 계산됩니다.
A10: 월별집계 | B10: 조회할 연월 하나만 바꾸면 그 달의 근무일수·지각·결근·연차사용이 직원별로 집계됩니다.
A11: 프로젝트집계 | B11: 근태기록의 「프로젝트」 칸을 모아 프로젝트별 투입시간을 집계합니다. 견적의 근거가 됩니다.
A12: 보상휴가 | B12: 연장·야간·휴일근로 수당을 갈음하는 휴가의 발생·사용·잔여를 관리합니다.
A13: 코드표 | B13: 드롭다운 목록의 원본입니다. 항목을 늘리려면 여기에 추가합니다.
A15: 연차 계산 기준
A16: 산정 기준일 | B16: 입사일 기준입니다. 사람마다 연차 발생일이 다릅니다. (취업규칙 제22조제3항)
A17: 1년 미만 | B17: 1개월 개근할 때마다 1일씩, 최대 11일. 입사 1주년 전날까지 써야 하고 남으면 소멸합니다.
A18: 1년 이상 | B18: 15일. 3년 이상 근속부터 2년마다 1일씩 늘어나며 최대 25일입니다.
A19: 반차 | B19: 휴가대장의 「일수」 칸에 0.5를 넣으면 반차로 집계됩니다.
A20: 미사용분 | B20: 산정기간이 끝나면 소멸하며, 소멸한 일수만큼 미사용 수당을 지급합니다. (취업규칙 제23조제4항)
A22: 꼭 알아두실 점
A23: 월차는 없습니다 | B23: 월차휴가는 2003년 근로기준법 개정으로 폐지된 제도입니다. 지금 「월차」라고 부르는 것은 입사 1년 미만 직원에게 매월 1일씩 생기는 연차(최대 11일)를 가리키며, 이 대장에서는 연차현황 시트에 함께 계산됩니다.
A24: 5인 미만 | B24: 연차유급휴가는 상시 근로자 5명 미만 사업장에 법적으로 강제되지 않습니다. 마인드는 취업규칙 제22조로 이를 부여하기로 정했으므로, 그 시점부터 회사의 의무가 됩니다.
A25: 보존 의무 | B25: 근태기록과 임금 관련 서류는 3년간 보존해야 합니다. (근로기준법 제42조)
A26: 5인이 되면 | B26: 상시 5명 이상이 되는 순간 연차유급휴가·연차사용촉진·주 12시간 연장 한도가 법적 의무로 전환됩니다. 가산수당은 이미 취업규칙으로 지급하고 있습니다.
A28: ※ | B28: 이 대장은 취업규칙 초안을 전제로 만든 관리 도구입니다. 취업규칙의 연차 조항을 바꾸면 연차현황 시트의 계산식(H열)도 함께 고쳐야 합니다.

Sheet 직원명부
A1: 직원명부
A2: 가장 먼저 채우는 시트입니다. 사번은 다른 시트에서 사람을 찾는 열쇠이므로 중복되면 안 됩니다.
A3: 입력 방법 : 파란 글씨 = 직접 입력하는 칸 · 검은 글씨 + 회색 배경 = 자동 계산 (수정 금지)
A4: 사번 | B4: 성명 | C4: 입사일 | D4: 직위 | E4: 고용형태 | F4: 재직상태 | G4: 퇴사일 | H4: 연봉 (원) | I4: 월 지급액 | J4: 주 소정근로시간 | K4: 비고
A5: M001 | B5: 강성아 | C5: 46034 | D5: UI·UX 디자이너 | E5: 정규사원 | F5: 재직 | H5: 32000000 | I5: =IF(H5="","",ROUND(H5/12,0)) | J5: 40 | K5: 수습 2026-01-12 ~ 2026-04-11 종료
I6: =IF(H6="","",ROUND(H6/12,0))
I7: =IF(H7="","",ROUND(H7/12,0))
I8: =IF(H8="","",ROUND(H8/12,0))
I9: =IF(H9="","",ROUND(H9/12,0))
I10: =IF(H10="","",ROUND(H10/12,0))
I11: =IF(H11="","",ROUND(H11/12,0))
I12: =IF(H12="","",ROUND(H12/12,0))
I13: =IF(H13="","",ROUND(H13/12,0))
I14: =IF(H14="","",ROUND(H14/12,0))
I15: =IF(H15="","",ROUND(H15/12,0))
I16: =IF(H16="","",ROUND(H16/12,0))
I17: =IF(H17="","",ROUND(H17/12,0))
... I24: =IF(H24="","",ROUND(H24/12,0))

Sheet 연차현황
A1: 연차현황
A2: 입사일 기준 자동 계산입니다. 직접 입력하는 칸은 「이월」 하나뿐입니다.
A3: 기준일 | B3: =TODAY() | C3: ← 특정 시점 기준으로 보려면 이 칸에 날짜를 직접 넣으세요.
A4: 사번 | B4: 성명 | C4: 입사일 | D4: 재직상태 | E4: 근속 | F4: 산정기간 시작 | G4: 산정기간 종료 | H4: 발생일수 | I4: 이월 | J4: 총 부여 | K4: 사용 | L4: 잔여 | M4: 소멸까지
A5: =IF(직원명부!A5="","",직원명부!A5) | B5: =IF(직원명부!B5="","",직원명부!B5) | C5: =IF(직원명부!C5="","",직원명부!C5) | D5: =IF(직원명부!F5="","",직원명부!F5) | E5: =IF(C5="","",DATEDIF(C5,IF(직원명부!G5="",$B$3,MIN($B$3,직원명부!G5)),"Y")&"년 "&DATEDIF(C5,IF(직원명부!G5="",$B$3,MIN($B$3,직원명부!G5)),"YM")&"개월") | F5: =IF(C5="","",IF(DATEDIF(C5,IF(직원명부!G5="",$B$3,MIN($B$3,직원명부!G5)),"Y")<1,C5,EDATE(C5,DATEDIF(C5,IF(직원명부!G5="",$B$3,MIN($B$3,직원명부!G5)),"Y")*12))) | G5: =IF(C5="","",EDATE(C5,(DATEDIF(C5,IF(직원명부!G5="",$B$3,MIN($B$3,직원명부!G5)),"Y")+1)*12)-1) | H5: =IF(C5="","",IF(DATEDIF(C5,IF(직원명부!G5="",$B$3,MIN($B$3,직원명부!G5)),"Y")<1,MIN(11,DATEDIF(C5,IF(직원명부!G5="",$B$3,MIN($B$3,직원명부!G5)),"M")),MIN(25,15+INT((DATEDIF(C5,IF(직원명부!G5="",$B$3,MIN($B$3,직원명부!G5)),"Y")-1)/2)))) | J5: =IF(C5="","",H5+N(I5)) | K5: =IF(C5="","",SUMIFS(휴가대장!$F$5:$F$504,휴가대장!$B$5:$B$504,$A5,휴가대장!$E$5:$E$504,"연차",휴가대장!$D$5:$D$504,">="&$F5,휴가대장!$D$5:$D$504,"<="&$G5)) | L5: =IF(C5="","",J5-K5) | M5: =IF(C5="","",IF(직원명부!G5<>"","퇴사",IF(G5-$B$3<0,"기간종료",G5-$B$3&"일")))
A6: =IF(직원명부!A6="","",직원명부!A6) | B6: =IF(직원명부!B6="","",직원명부!B6) | C6: =IF(직원명부!C6="","",직원명부!C6) | D6: =IF(직원명부!F6="","",직원명부!F6) | E6: =IF(C6="","",DATEDIF(C6,IF(직원명부!G6="",$B$3,MIN($B$3,직원명부!G6)),"Y")&"년 "&DATEDIF(C6,IF(직원명부!G6="",$B$3,MIN($B$3,직원명부!G6)),"YM")&"개월") | F6: =IF(C6="","",IF(DATEDIF(C6,IF(직원명부!G6="",$B$3,MIN($B$3,직원명부!G6)),"Y")<1,C6,EDATE(C6,DATEDIF(C6,IF(직원명부!G6="",$B$3,MIN($B$3,직원명부!G6)),"Y")*12))) | G6: =IF(C6="","",EDATE(C6,(DATEDIF(C6,IF(직원명부!G6="",$B$3,MIN($B$3,직원명부!G6)),"Y")+1)*12)-1) | H6: =IF(C6="","",IF(DATEDIF(C6,IF(직원명부!G6="",$B$3,MIN($B$3,직원명부!G6)),"Y")<1,MIN(11,DATEDIF(C6,IF(직원명부!G6="",$B$3,MIN($B$3,직원명부!G6)),"M")),MIN(25,15+INT((DATEDIF(C6,IF(직원명부!G6="",$B$3,MIN($B$3,직원명부!G6)),"Y")-1)/2)))) | J6: =IF(C6="","",H6+N(I6)) | K6: =IF(C6="","",SUMIFS(휴가대장!$F$5:$F$504,휴가대장!$B$5:$B$504,$A6,휴가대장!$E$5:$E$504,"연차",휴가대장!$D$5:$D$504,">="&$F6,휴가대장!$D$5:$D$504,"<="&$G6)) | L6: =IF(C6="","",J6-K6) | M6: =IF(C6="","",IF(직원명부!G6<>"","퇴사",IF(G6-$B$3<0,"기간종료",G6-$B$3&"일")))
A7: =IF(직원명부!A7="","",직원명부!A7) | B7: =IF(직원명부!B7="","",직원명부!B7) | C7: =IF(직원명부!C7="","",직원명부!C7) | D7: =IF(직원명부!F7="","",직원명부!F7) | E7: =IF(C7="","",DATEDIF(C7,IF(직원명부!G7="",$B$3,MIN($B$3,직원명부!G7)),"Y")&"년 "&DATEDIF(C7,IF(직원명부!G7="",$B$3,MIN($B$3,직원명부!G7)),"YM")&"개월") | F7: =IF(C7="","",IF(DATEDIF(C7,IF(직원명부!G7="",$B$3,MIN($B$3,직원명부!G7)),"Y")<1,C7,EDATE(C7,DATEDIF(C7,IF(직원명부!G7="",$B$3,MIN($B$3,직원명부!G7)),"Y")*12))) | G7: =IF(C7="","",EDATE(C7,(DATEDIF(C7,IF(직원명부!G7="",$B$3,MIN($B$3,직원명부!G7)),"Y")+1)*12)-1) | H7: =IF(C7="","",IF(DATEDIF(C7,IF(직원명부!G7="",$B$3,MIN($B$3,직원명부!G7)),"Y")<1,MIN(11,DATEDIF(C7,IF(직원명부!G7="",$B$3,MIN($B$3,직원명부!G7)),"M")),MIN(25,15+INT((DATEDIF(C7,IF(직원명부!G7="",$B$3,MIN($B$3,직원명부!G7)),"Y")-1)/2)))) | J7: =IF(C7="","",H7+N(I7)) | K7: =IF(C7="","",SUMIFS(휴가대장!$F$5:$F$504,휴가대장!$B$5:$B$504,$A7,휴가대장!$E$5:$E$504,"연차",휴가대장!$D$5:$D$504,">="&$F7,휴가대장!$D$5:$D$504,"<="&$G7)) | L7: =IF(C7="","",J7-K7) | M7: =IF(C7="","",IF(직원명부!G7<>"","퇴사",IF(G7-$B$3<0,"기간종료",G7-$B$3&"일")))
A8: =IF(직원명부!A8="","",직원명부!A8) | B8: =IF(직원명부!B8="","",직원명부!B8) | C8: =IF(직원명부!C8="","",직원명부!C8) | D8: =IF(직원명부!F8="","",직원명부!F8) | E8: =IF(C8="","",DATEDIF(C8,IF(직원명부!G8="",$B$3,MIN($B$3,직원명부!G8)),"Y")&"년 "&DATEDIF(C8,IF(직원명부!G8="",$B$3,MIN($B$3,직원명부!G8)),"YM")&"개월") | F8: =IF(C8="","",IF(DATEDIF(C8,IF(직원명부!G8="",$B$3,MIN($B$3,직원명부!G8)),"Y")<1,C8,EDATE(C8,DATEDIF(C8,IF(직원명부!G8="",$B$3,MIN($B$3,직원명부!G8)),"Y")*12))) | G8: =IF(C8="","",EDATE(C8,(DATEDIF(C8,IF(직원명부!G8="",$B$3,MIN($B$3,직원명부!G8)),"Y")+1)*12)-1) | H8: =IF(C8="","",IF(DATEDIF(C8,IF(직원명부!G8="",$B$3,MIN($B$3,직원명부!G8)),"Y")<1,MIN(11,DATEDIF(C8,IF(직원명부!G8="",$B$3,MIN($B$3,직원명부!G8)),"M")),MIN(25,15+INT((DATEDIF(C8,IF(직원명부!G8="",$B$3,MIN($B$3,직원명부!G8)),"Y")-1)/2)))) | J8: =IF(C8="","",H8+N(I8)) | K8: =IF(C8="","",SUMIFS(휴가대장!$F$5:$F$504,휴가대장!$B$5:$B$504,$A8,휴가대장!$E$5:$E$504,"연차",휴가대장!$D$5:$D$504,">="&$F8,휴가대장!$D$5:$D$504,"<="&$G8)) | L8: =IF(C8="","",J8-K8) | M8: =IF(C8="","",IF(직원명부!G8<>"","퇴사",IF(G8-$B$3<0,"기간종료",G8-$B$3&"일")))
A9: =IF(직원명부!A9="","",직원명부!A9) | B9: =IF(직원명부!B9="","",직원명부!B9) | C9: =IF(직원명부!C9="","",직원명부!C9) | D9: =IF(직원명부!F9="","",직원명부!F9) | E9: =IF(C9="","",DATEDIF(C9,IF(직원명부!G9="",$B$3,MIN($B$3,직원명부!G9)),"Y")&"년 "&DATEDIF(C9,IF(직원명부!G9="",$B$3,MIN($B$3,직원명부!G9)),"YM")&"개월") | F9: =IF(C9="","",IF(DATEDIF(C9,IF(직원명부!G9="",$B$3,MIN($B$3,직원명부!G9)),"Y")<1,C9,EDATE(C9,DATEDIF(C9,IF(직원명부!G9="",$B$3,MIN($B$3,직원명부!G9)),"Y")*12))) | G9: =IF(C9="","",EDATE(C9,(DATEDIF(C9,IF(직원명부!G9="",$B$3,MIN($B$3,직원명부!G9)),"Y")+1)*12)-1) | H9: =IF(C9="","",IF(DATEDIF(C9,IF(직원명부!G9="",$B$3,MIN($B$3,직원명부!G9)),"Y")<1,MIN(11,DATEDIF(C9,IF(직원명부!G9="",$B$3,MIN($B$3,직원명부!G9)),"M")),MIN(25,15+INT((DATEDIF(C9,IF(직원명부!G9="",$B$3,MIN($B$3,직원명부!G9)),"Y")-1)/2)))) | J9: =IF(C9="","",H9+N(I9)) | K9: =IF(C9="","",SUMIFS(휴가대장!$F$5:$F$504,휴가대장!$B$5:$B$504,$A9,휴가대장!$E$5:$E$504,"연차",휴가대장!$D$5:$D$504,">="&$F9,휴가대장!$D$5:$D$504,"<="&$G9)) | L9: =IF(C9="","",J9-K9) | M9: =IF(C9="","",IF(직원명부!G9<>"","퇴사",IF(G9-$B$3<0,"기간종료",G9-$B$3&"일")))
A10: =IF(직원명부!A10="","",직원명부!A10) | B10: =IF(직원명부!B10="","",직원명부!B10) | C10: =IF(직원명부!C10="","",직원명부!C10) | D10: =IF(직원명부!F10="","",직원명부!F10) | E10: =IF(C10="","",DATEDIF(C10,IF(직원명부!G10="",$B$3,MIN($B$3,직원명부!G10)),"Y")&"년 "&DATEDIF(C10,IF(직원명부!G10="",$B$3,MIN($B$3,직원명부!G10)),"YM")&"개월") | F10: =IF(C10="","",IF(DATEDIF(C10,IF(직원명부!G10="",$B$3,MIN($B$3,직원명부!G10)),"Y")<1,C10,EDATE(C10,DATEDIF(C10,IF(직원명부!G10="",$B$3,MIN($B$3,직원명부!G10)),"Y")*12))) | G10: =IF(C10="","",EDATE(C10,(DATEDIF(C10,IF(직원명부!G10="",$B$3,MIN($B$3,직원명부!G10)),"Y")+1)*12)-1) | H10: =IF(C10="","",IF(DATEDIF(C10,IF(직원명부!G10="",$B$3,MIN($B$3,직원명부!G10)),"Y")<1,MIN(11,DATEDIF(C10,IF(직원명부!G10="",$B$3,MIN($B$3,직원명부!G10)),"M")),MIN(25,15+INT((DATEDIF(C10,IF(직원명부!G10="",$B$3,MIN($B$3,직원명부!G10)),"Y")-1)/2)))) | J10: =IF(C10="","",H10+N(I10)) | K10: =IF(C10="","",SUMIFS(휴가대장!$F$5:$F$504,휴가대장!$B$5:$B$504,$A10,휴가대장!$E$5:$E$504,"연차",휴가대장!$D$5:$D$504,">="&$F10,휴가대장!$D$5:$D$504,"<="&$G10)) | L10: =IF(C10="","",J10-K10) | M10: =IF(C10="","",IF(직원명부!G10<>"","퇴사",IF(G10-$B$3<0,"기간종료",G10-$B$3&"일")))
A11: =IF(직원명부!A11="","",직원명부!A11) | B11: =IF(직원명부!B11="","",직원명부!B11) | C11: =IF(직원명부!C11="","",직원명부!C11) | D11: =IF(직원명부!F11="","",직원명부!F11) | E11: =IF(C11="","",DATEDIF(C11,IF(직원명부!G11="",$B$3,MIN($B$3,직원명부!G11)),"Y")&"년 "&DATEDIF(C11,IF(직원명부!G11="",$B$3,MIN($B$3,직원명부!G11)),"YM")&"개월") | F11: =IF(C11="","",IF(DATEDIF(C11,IF(직원명부!G11="",$B$3,MIN($B$3,직원명부!G11)),"Y")<1,C11,EDATE(C11,DATEDIF(C11,IF(직원명부!G11="",$B$3,MIN($B$3,직원명부!G11)),"Y")*12))) | G11: =IF(C11="","",EDATE(C11,(DATEDIF(C11,IF(직원명부!G11="",$B$3,MIN($B$3,직원명부!G11)),"Y")+1)*12)-1) | H11: =IF(C11="","",IF(DATEDIF(C11,IF(직원명부!G11="",$B$3,MIN($B$3,직원명부!G11)),"Y")<1,MIN(11,DATEDIF(C11,IF(직원명부!G11="",$B$3,MIN($B$3,직원명부!G11)),"M")),MIN(25,15+INT((DATEDIF(C11,IF(직원명부!G11="",$B$3,MIN($B$3,직원명부!G11)),"Y")-1)/2)))) | J11: =IF(C11="","",H11+N(I11)) | K11: =IF(C11="","",SUMIFS(휴가대장!$F$5:$F$504,휴가대장!$B$5:$B$504,$A11,휴가대장!$E$5:$E$504,"연차",휴가대장!$D$5:$D$504,">="&$F11,휴가대장!$D$5:$D$504,"<="&$G11)) | L11: =IF(C11="","",J11-K11) | M11: =IF(C11="","",IF(직원명부!G11<>"","퇴사",IF(G11-$B$3<0,"기간종료",G11-$B$3&"일")))
A12: =IF(직원명부!A12="","",직원명부!A12) | B12: =IF(직원명부!B12="","",직원명부!B12) | C12: =IF(직원명부!C12="","",직원명부!C12) | D12: =IF(직원명부!F12="","",직원명부!F12) | E12: =IF(C12="","",DATEDIF(C12,IF(직원명부!G12="",$B$3,MIN($B$3,직원명부!G12)),"Y")&"년 "&DATEDIF(C12,IF(직원명부!G12="",$B$3,MIN($B$3,직원명부!G12)),"YM")&"개월") | F12: =IF(C12="","",IF(DATEDIF(C12,IF(직원명부!G12="",$B$3,MIN($B$3,직원명부!G12)),"Y")<1,C12,EDATE(C12,DATEDIF(C12,IF(직원명부!G12="",$B$3,MIN($B$3,직원명부!G12)),"Y")*12))) | G12: =IF(C12="","",EDATE(C12,(DATEDIF(C12,IF(직원명부!G12="",$B$3,MIN($B$3,직원명부!G12)),"Y")+1)*12)-1) | H12: =IF(C12="","",IF(DATEDIF(C12,IF(직원명부!G12="",$B$3,MIN($B$3,직원명부!G12)),"Y")<1,MIN(11,DATEDIF(C12,IF(직원명부!G12="",$B$3,MIN($B$3,직원명부!G12)),"M")),MIN(25,15+INT((DATEDIF(C12,IF(직원명부!G12="",$B$3,MIN($B$3,직원명부!G12)),"Y")-1)/2)))) | J12: =IF(C12="","",H12+N(I12)) | K12: =IF(C12="","",SUMIFS(휴가대장!$F$5:$F$504,휴가대장!$B$5:$B$504,$A12,휴가대장!$E$5:$E$504,"연차",휴가대장!$D$5:$D$504,">="&$F12,휴가대장!$D$5:$D$504,"<="&$G12)) | L12: =IF(C12="","",J12-K12) | M12: =IF(C12="","",IF(직원명부!G12<>"","퇴사",IF(G12-$B$3<0,"기간종료",G12-$B$3&"일")))
A13: =IF(직원명부!A13="","",직원명부!A13) | B13: =IF(직원명부!B13="","",직원명부!B13) | C13: =IF(직원명부!C13="","",직원명부!C13) | D13: =IF(직원명부!F13="","",직원명부!F13) | E13: =IF(C13="","",DATEDIF(C13,IF(직원명부!G13="",$B$3,MIN($B$3,직원명부!G13)),"Y")&"년 "&DATEDIF(C13,IF(직원명부!G13="",$B$3,MIN($B$3,직원명부!G13)),"YM")&"개월") | F13: =IF(C13="","",IF(DATEDIF(C13,IF(직원명부!G13="",$B$3,MIN($B$3,직원명부!G13)),"Y")<1,C13,EDATE(C13,DATEDIF(C13,IF(직원명부!G13="",$B$3,MIN($B$3,직원명부!G13)),"Y")*12))) | G13: =IF(C13="","",EDATE(C13,(DATEDIF(C13,IF(직원명부!G13="",$B$3,MIN($B$3,직원명부!G13)),"Y")+1)*12)-1) | H13: =IF(C13="","",IF(DATEDIF(C13,IF(직원명부!G13="",$B$3,MIN($B$3,직원명부!G13)),"Y")<1,MIN(11,DATEDIF(C13,IF(직원명부!G13="",$B$3,MIN($B$3,직원명부!G13)),"M")),MIN(25,15+INT((DATEDIF(C13,IF(직원명부!G13="",$B$3,MIN($B$3,직원명부!G13)),"Y")-1)/2)))) | J13: =IF(C13="","",H13+N(I13)) | K13: =IF(C13="","",SUMIFS(휴가대장!$F$5:$F$504,휴가대장!$B$5:$B$504,$A13,휴가대장!$E$5:$E$504,"연차",휴가대장!$D$5:$D$504,">="&$F13,휴가대장!$D$5:$D$504,"<="&$G13)) | L13: =IF(C13="","",J13-K13) | M13: =IF(C13="","",IF(직원명부!G13<>"","퇴사",IF(G13-$B$3<0,"기간종료",G13-$B$3&"일")))
A14: =IF(직원명부!A14="","",직원명부!A14) | B14: =IF(직원명부!B14="","",직원명부!B14) | C14: =IF(직원명부!C14="","",직원명부!C14) | D14: =IF(직원명부!F14="","",직원명부!F14) | E14: =IF(C14="","",DATEDIF(C14,IF(직원명부!G14="",$B$3,MIN($B$3,직원명부!G14)),"Y")&"년 "&DATEDIF(C14,IF(직원명부!G14="",$B$3,MIN($B$3,직원명부!G14)),"YM")&"개월") | F14: =IF(C14="","",IF(DATEDIF(C14,IF(직원명부!G14="",$B$3,MIN($B$3,직원명부!G14)),"Y")<1,C14,EDATE(C14,DATEDIF(C14,IF(직원명부!G14="",$B$3,MIN($B$3,직원명부!G14)),"Y")*12))) | G14: =IF(C14="","",EDATE(C14,(DATEDIF(C14,IF(직원명부!G14="",$B$3,MIN($B$3,직원명부!G14)),"Y")+1)*12)-1) | H14: =IF(C14="","",IF(DATEDIF(C14,IF(직원명부!G14="",$B$3,MIN($B$3,직원명부!G14)),"Y")<1,MIN(11,DATEDIF(C14,IF(직원명부!G14="",$B$3,MIN($B$3,직원명부!G14)),"M")),MIN(25,15+INT((DATEDIF(C14,IF(직원명부!G14="",$B$3,MIN($B$3,직원명부!G14)),"Y")-1)/2)))) | J14: =IF(C14="","",H14+N(I14)) | K14: =IF(C14="","",SUMIFS(휴가대장!$F$5:$F$504,휴가대장!$B$5:$B$504,$A14,휴가대장!$E$5:$E$504,"연차",휴가대장!$D$5:$D$504,">="&$F14,휴가대장!$D$5:$D$504,"<="&$G14)) | L14: =IF(C14="","",J14-K14) | M14: =IF(C14="","",IF(직원명부!G14<>"","퇴사",IF(G14-$B$3<0,"기간종료",G14-$B$3&"일")))
A15: =IF(직원명부!A15="","",직원명부!A15) | B15: =IF(직원명부!B15="","",직원명부!B15) | C15: =IF(직원명부!C15="","",직원명부!C15) | D15: =IF(직원명부!F15="","",직원명부!F15) | E15: =IF(C15="","",DATEDIF(C15,IF(직원명부!G15="",$B$3,MIN($B$3,직원명부!G15)),"Y")&"년 "&DATEDIF(C15,IF(직원명부!G15="",$B$3,MIN($B$3,직원명부!G15)),"YM")&"개월") | F15: =IF(C15="","",IF(DATEDIF(C15,IF(직원명부!G15="",$B$3,MIN($B$3,직원명부!G15)),"Y")<1,C15,EDATE(C15,DATEDIF(C15,IF(직원명부!G15="",$B$3,MIN($B$3,직원명부!G15)),"Y")*12))) | G15: =IF(C15="","",EDATE(C15,(DATEDIF(C15,IF(직원명부!G15="",$B$3,MIN($B$3,직원명부!G15)),"Y")+1)*12)-1) | H15: =IF(C15="","",IF(DATEDIF(C15,IF(직원명부!G15="",$B$3,MIN($B$3,직원명부!G15)),"Y")<1,MIN(11,DATEDIF(C15,IF(직원명부!G15="",$B$3,MIN($B$3,직원명부!G15)),"M")),MIN(25,15+INT((DATEDIF(C15,IF(직원명부!G15="",$B$3,MIN($B$3,직원명부!G15)),"Y")-1)/2)))) | J15: =IF(C15="","",H15+N(I15)) | K15: =IF(C15="","",SUMIFS(휴가대장!$F$5:$F$504,휴가대장!$B$5:$B$504,$A15,휴가대장!$E$5:$E$504,"연차",휴가대장!$D$5:$D$504,">="&$F15,휴가대장!$D$5:$D$504,"<="&$G15)) | L15: =IF(C15="","",J15-K15) | M15: =IF(C15="","",IF(직원명부!G15<>"","퇴사",IF(G15-$B$3<0,"기간종료",G15-$B$3&"일")))
A16: =IF(직원명부!A16="","",직원명부!A16) | B16: =IF(직원명부!B16="","",직원명부!B16) | C16: =IF(직원명부!C16="","",직원명부!C16) | D16: =IF(직원명부!F16="","",직원명부!F16) | E16: =IF(C16="","",DATEDIF(C16,IF(직원명부!G16="",$B$3,MIN($B$3,직원명부!G16)),"Y")&"년 "&DATEDIF(C16,IF(직원명부!G16="",$B$3,MIN($B$3,직원명부!G16)),"YM")&"개월") | F16: =IF(C16="","",IF(DATEDIF(C16,IF(직원명부!G16="",$B$3,MIN($B$3,직원명부!G16)),"Y")<1,C16,EDATE(C16,DATEDIF(C16,IF(직원명부!G16="",$B$3,MIN($B$3,직원명부!G16)),"Y")*12))) | G16: =IF(C16="","",EDATE(C16,(DATEDIF(C16,IF(직원명부!G16="",$B$3,MIN($B$3,직원명부!G16)),"Y")+1)*12)-1) | H16: =IF(C16="","",IF(DATEDIF(C16,IF(직원명부!G16="",$B$3,MIN($B$3,직원명부!G16)),"Y")<1,MIN(11,DATEDIF(C16,IF(직원명부!G16="",$B$3,MIN($B$3,직원명부!G16)),"M")),MIN(25,15+INT((DATEDIF(C16,IF(직원명부!G16="",$B$3,MIN($B$3,직원명부!G16)),"Y")-1)/2)))) | J16: =IF(C16="","",H16+N(I16)) | K16: =IF(C16="","",SUMIFS(휴가대장!$F$5:$F$504,휴가대장!$B$5:$B$504,$A16,휴가대장!$E$5:$E$504,"연차",휴가대장!$D$5:$D$504,">="&$F16,휴가대장!$D$5:$D$504,"<="&$G16)) | L16: =IF(C16="","",J16-K16) | M16: =IF(C16="","",IF(직원명부!G16<>"","퇴사",IF(G16-$B$3<0,"기간종료",G16-$B$3&"일")))
... A24: =IF(직원명부!A24="","",직원명부!A24) | B24: =IF(직원명부!B24="","",직원명부!B24) | C24: =IF(직원명부!C24="","",직원명부!C24) | D24: =IF(직원명부!F24="","",직원명부!F24) | E24: =IF(C24="","",DATEDIF(C24,IF(직원명부!G24="",$B$3,MIN($B$3,직원명부!G24)),"Y")&"년 "&DATEDIF(C24,IF(직원명부!G24="",$B$3,MIN($B$3,직원명부!G24)),"YM")&"개월") | F24: =IF(C24="","",IF(DATEDIF(C24,IF(직원명부!G24="",$B$3,MIN($B$3,직원명부!G24)),"Y")<1,C24,EDATE(C24,DATEDIF(C24,IF(직원명부!G24="",$B$3,MIN($B$3,직원명부!G24)),"Y")*12))) | G24: =IF(C24="","",EDATE(C24,(DATEDIF(C24,IF(직원명부!G24="",$B$3,MIN($B$3,직원명부!G24)),"Y")+1)*12)-1) | H24: =IF(C24="","",IF(DATEDIF(C24,IF(직원명부!G24="",$B$3,MIN($B$3,직원명부!G24)),"Y")<1,MIN(11,DATEDIF(C24,IF(직원명부!G24="",$B$3,MIN($B$3,직원명부!G24)),"M")),MIN(25,15+INT((DATEDIF(C24,IF(직원명부!G24="",$B$3,MIN($B$3,직원명부!G24)),"Y")-1)/2)))) | J24: =IF(C24="","",H24+N(I24)) | K24: =IF(C24="","",SUMIFS(휴가대장!$F$5:$F$504,휴가대장!$B$5:$B$504,$A24,휴가대장!$E$5:$E$504,"연차",휴가대장!$D$5:$D$504,">="&$F24,휴가대장!$D$5:$D$504,"<="&$G24)) | L24: =IF(C24="","",J24-K24) | M24: =IF(C24="","",IF(직원명부!G24<>"","퇴사",IF(G24-$B$3<0,"기간종료",G24-$B$3&"일")))
A26: · 「발생일수」는 개근을 전제로 계산합니다. 결근이 있어 출근율 80% 미만인 직원은 수동으로 조정하세요.
A27: · 「사용」은 휴가대장에서 종류가 「연차」이고 사용일자가 산정기간 안에 있는 건만 더합니다. 경조·병가는 빠집니다.
A28: · 산정기간이 끝나면 잔여일수는 소멸하며, 소멸분에 대해 미사용 수당을 지급해야 합니다. (취업규칙 제23조제4항)

Sheet 휴가대장
A1: 휴가대장
A2: 휴가를 쓸 때마다 한 줄씩 기록합니다. 종류가 「연차」인 건만 연차현황의 사용일수에 반영됩니다.
A3: 입력 방법 : 파란 글씨 = 직접 입력하는 칸 · 검은 글씨 + 회색 배경 = 자동 계산 (수정 금지) | E3: 반차는 일수 칸에 0.5를 넣으세요. · 연속 휴가는 날짜별로 한 줄씩 나눠 적는 것이 집계에 정확합니다.
A4: 순번 | B4: 사번 | C4: 성명 | D4: 사용일자 | E4: 휴가종류 | F4: 일수 | G4: 사유 | H4: 승인자 | I4: 신청일
A5: =IF(B5="","",COUNTA($B$5:$B5)) | C5: =IFERROR(IF(B5="","",INDEX(직원명부!$B$5:$B$24,MATCH(B5,직원명부!$A$5:$A$24,0))),"사번 확인")
A6: =IF(B6="","",COUNTA($B$5:$B6)) | C6: =IFERROR(IF(B6="","",INDEX(직원명부!$B$5:$B$24,MATCH(B6,직원명부!$A$5:$A$24,0))),"사번 확인")
A7: =IF(B7="","",COUNTA($B$5:$B7)) | C7: =IFERROR(IF(B7="","",INDEX(직원명부!$B$5:$B$24,MATCH(B7,직원명부!$A$5:$A$24,0))),"사번 확인")
A8: =IF(B8="","",COUNTA($B$5:$B8)) | C8: =IFERROR(IF(B8="","",INDEX(직원명부!$B$5:$B$24,MATCH(B8,직원명부!$A$5:$A$24,0))),"사번 확인")
A9: =IF(B9="","",COUNTA($B$5:$B9)) | C9: =IFERROR(IF(B9="","",INDEX(직원명부!$B$5:$B$24,MATCH(B9,직원명부!$A$5:$A$24,0))),"사번 확인")
A10: =IF(B10="","",COUNTA($B$5:$B10)) | C10: =IFERROR(IF(B10="","",INDEX(직원명부!$B$5:$B$24,MATCH(B10,직원명부!$A$5:$A$24,0))),"사번 확인")
A11: =IF(B11="","",COUNTA($B$5:$B11)) | C11: =IFERROR(IF(B11="","",INDEX(직원명부!$B$5:$B$24,MATCH(B11,직원명부!$A$5:$A$24,0))),"사번 확인")
A12: =IF(B12="","",COUNTA($B$5:$B12)) | C12: =IFERROR(IF(B12="","",INDEX(직원명부!$B$5:$B$24,MATCH(B12,직원명부!$A$5:$A$24,0))),"사번 확인")
A13: =IF(B13="","",COUNTA($B$5:$B13)) | C13: =IFERROR(IF(B13="","",INDEX(직원명부!$B$5:$B$24,MATCH(B13,직원명부!$A$5:$A$24,0))),"사번 확인")
A14: =IF(B14="","",COUNTA($B$5:$B14)) | C14: =IFERROR(IF(B14="","",INDEX(직원명부!$B$5:$B$24,MATCH(B14,직원명부!$A$5:$A$24,0))),"사번 확인")
A15: =IF(B15="","",COUNTA($B$5:$B15)) | C15: =IFERROR(IF(B15="","",INDEX(직원명부!$B$5:$B$24,MATCH(B15,직원명부!$A$5:$A$24,0))),"사번 확인")
A16: =IF(B16="","",COUNTA($B$5:$B16)) | C16: =IFERROR(IF(B16="","",INDEX(직원명부!$B$5:$B$24,MATCH(B16,직원명부!$A$5:$A$24,0))),"사번 확인")
... A504: =IF(B504="","",COUNTA($B$5:$B504)) | C504: =IFERROR(IF(B504="","",INDEX(직원명부!$B$5:$B$24,MATCH(B504,직원명부!$A$5:$A$24,0))),"사번 확인")

Sheet 근태기록
A1: 근태기록
A2: 출퇴근 시각을 매일 기록합니다. 근로기준법 제42조에 따라 3년간 보존해야 합니다.
A3: 입력 방법 : 파란 글씨 = 직접 입력하는 칸 · 검은 글씨 + 회색 배경 = 자동 계산 (수정 금지) | E3: 시각은 09:00 형식으로 입력합니다. · 휴게시간은 시간 단위 숫자(1 = 1시간)로 넣습니다. · 자정을 넘겨 퇴근한 경우에도 퇴근 시각만 그대로 적으면 근무시간이 맞게 계산됩니다.
A4: 날짜 | B4: 요일 | C4: 사번 | D4: 성명 | E4: 출근 | F4: 퇴근 | G4: 휴게(h) | H4: 근무시간 | I4: 연장시간 | J4: 야간시간 | K4: 보상휴가 | L4: 근태구분 | M4: 프로젝트 | N4: 비고
A5: 46034 | B5: =IF(A5="","",CHOOSE(WEEKDAY(A5,2),"월","화","수","목","금","토","일")) | C5: M001 | D5: =IFERROR(IF(C5="","",INDEX(직원명부!$B$5:$B$24,MATCH(C5,직원명부!$A$5:$A$24,0))),"사번 확인") | E5: 0.375 | F5: 0.75 | G5: 1 | H5: =IF(OR(E5="",F5=""),"",ROUND(MOD(F5-E5,1)*24-N(G5),2)) | I5: =IF(H5="","",ROUND(MAX(0,H5-8),2)) | J5: =IF(OR(E5="",F5=""),"",ROUND(IF(MOD(F5,1)>=TIME(22,0,0),(MOD(F5,1)-TIME(22,0,0))*24,IF(MOD(F5,1)<TIME(6,0,0),(MOD(F5,1)+1-TIME(22,0,0))*24,0)),2)) | K5: =IF(H5="","",ROUND(IF(L5="휴일근로",MIN(H5,8)*1.5+MAX(0,H5-8)*2,I5*1.5)+N(J5)*0.5,2)) | L5: 정상
A6: 46035 | B6: =IF(A6="","",CHOOSE(WEEKDAY(A6,2),"월","화","수","목","금","토","일")) | C6: M001 | D6: =IFERROR(IF(C6="","",INDEX(직원명부!$B$5:$B$24,MATCH(C6,직원명부!$A$5:$A$24,0))),"사번 확인") | E6: 0.375 | F6: 0.75 | G6: 1 | H6: =IF(OR(E6="",F6=""),"",ROUND(MOD(F6-E6,1)*24-N(G6),2)) | I6: =IF(H6="","",ROUND(MAX(0,H6-8),2)) | J6: =IF(OR(E6="",F6=""),"",ROUND(IF(MOD(F6,1)>=TIME(22,0,0),(MOD(F6,1)-TIME(22,0,0))*24,IF(MOD(F6,1)<TIME(6,0,0),(MOD(F6,1)+1-TIME(22,0,0))*24,0)),2)) | K6: =IF(H6="","",ROUND(IF(L6="휴일근로",MIN(H6,8)*1.5+MAX(0,H6-8)*2,I6*1.5)+N(J6)*0.5,2)) | L6: 정상
A7: 46036 | B7: =IF(A7="","",CHOOSE(WEEKDAY(A7,2),"월","화","수","목","금","토","일")) | C7: M001 | D7: =IFERROR(IF(C7="","",INDEX(직원명부!$B$5:$B$24,MATCH(C7,직원명부!$A$5:$A$24,0))),"사번 확인") | E7: 0.375 | F7: 0.75 | G7: 1 | H7: =IF(OR(E7="",F7=""),"",ROUND(MOD(F7-E7,1)*24-N(G7),2)) | I7: =IF(H7="","",ROUND(MAX(0,H7-8),2)) | J7: =IF(OR(E7="",F7=""),"",ROUND(IF(MOD(F7,1)>=TIME(22,0,0),(MOD(F7,1)-TIME(22,0,0))*24,IF(MOD(F7,1)<TIME(6,0,0),(MOD(F7,1)+1-TIME(22,0,0))*24,0)),2)) | K7: =IF(H7="","",ROUND(IF(L7="휴일근로",MIN(H7,8)*1.5+MAX(0,H7-8)*2,I7*1.5)+N(J7)*0.5,2)) | L7: 정상
A8: 46037 | B8: =IF(A8="","",CHOOSE(WEEKDAY(A8,2),"월","화","수","목","금","토","일")) | C8: M001 | D8: =IFERROR(IF(C8="","",INDEX(직원명부!$B$5:$B$24,MATCH(C8,직원명부!$A$5:$A$24,0))),"사번 확인") | E8: 0.375 | F8: 0.75 | G8: 1 | H8: =IF(OR(E8="",F8=""),"",ROUND(MOD(F8-E8,1)*24-N(G8),2)) | I8: =IF(H8="","",ROUND(MAX(0,H8-8),2)) | J8: =IF(OR(E8="",F8=""),"",ROUND(IF(MOD(F8,1)>=TIME(22,0,0),(MOD(F8,1)-TIME(22,0,0))*24,IF(MOD(F8,1)<TIME(6,0,0),(MOD(F8,1)+1-TIME(22,0,0))*24,0)),2)) | K8: =IF(H8="","",ROUND(IF(L8="휴일근로",MIN(H8,8)*1.5+MAX(0,H8-8)*2,I8*1.5)+N(J8)*0.5,2)) | L8: 정상
A9: 46038 | B9: =IF(A9="","",CHOOSE(WEEKDAY(A9,2),"월","화","수","목","금","토","일")) | C9: M001 | D9: =IFERROR(IF(C9="","",INDEX(직원명부!$B$5:$B$24,MATCH(C9,직원명부!$A$5:$A$24,0))),"사번 확인") | E9: 0.375 | F9: 0.75 | G9: 1 | H9: =IF(OR(E9="",F9=""),"",ROUND(MOD(F9-E9,1)*24-N(G9),2)) | I9: =IF(H9="","",ROUND(MAX(0,H9-8),2)) | J9: =IF(OR(E9="",F9=""),"",ROUND(IF(MOD(F9,1)>=TIME(22,0,0),(MOD(F9,1)-TIME(22,0,0))*24,IF(MOD(F9,1)<TIME(6,0,0),(MOD(F9,1)+1-TIME(22,0,0))*24,0)),2)) | K9: =IF(H9="","",ROUND(IF(L9="휴일근로",MIN(H9,8)*1.5+MAX(0,H9-8)*2,I9*1.5)+N(J9)*0.5,2)) | L9: 정상
A10: 46039 | B10: =IF(A10="","",CHOOSE(WEEKDAY(A10,2),"월","화","수","목","금","토","일")) | C10: M001 | D10: =IFERROR(IF(C10="","",INDEX(직원명부!$B$5:$B$24,MATCH(C10,직원명부!$A$5:$A$24,0))),"사번 확인") | H10: =IF(OR(E10="",F10=""),"",ROUND(MOD(F10-E10,1)*24-N(G10),2)) | I10: =IF(H10="","",ROUND(MAX(0,H10-8),2)) | J10: =IF(OR(E10="",F10=""),"",ROUND(IF(MOD(F10,1)>=TIME(22,0,0),(MOD(F10,1)-TIME(22,0,0))*24,IF(MOD(F10,1)<TIME(6,0,0),(MOD(F10,1)+1-TIME(22,0,0))*24,0)),2)) | K10: =IF(H10="","",ROUND(IF(L10="휴일근로",MIN(H10,8)*1.5+MAX(0,H10-8)*2,I10*1.5)+N(J10)*0.5,2)) | N10: 주말
A11: 46040 | B11: =IF(A11="","",CHOOSE(WEEKDAY(A11,2),"월","화","수","목","금","토","일")) | C11: M001 | D11: =IFERROR(IF(C11="","",INDEX(직원명부!$B$5:$B$24,MATCH(C11,직원명부!$A$5:$A$24,0))),"사번 확인") | H11: =IF(OR(E11="",F11=""),"",ROUND(MOD(F11-E11,1)*24-N(G11),2)) | I11: =IF(H11="","",ROUND(MAX(0,H11-8),2)) | J11: =IF(OR(E11="",F11=""),"",ROUND(IF(MOD(F11,1)>=TIME(22,0,0),(MOD(F11,1)-TIME(22,0,0))*24,IF(MOD(F11,1)<TIME(6,0,0),(MOD(F11,1)+1-TIME(22,0,0))*24,0)),2)) | K11: =IF(H11="","",ROUND(IF(L11="휴일근로",MIN(H11,8)*1.5+MAX(0,H11-8)*2,I11*1.5)+N(J11)*0.5,2)) | N11: 주말
A12: 46041 | B12: =IF(A12="","",CHOOSE(WEEKDAY(A12,2),"월","화","수","목","금","토","일")) | C12: M001 | D12: =IFERROR(IF(C12="","",INDEX(직원명부!$B$5:$B$24,MATCH(C12,직원명부!$A$5:$A$24,0))),"사번 확인") | E12: 0.375 | F12: 0.75 | G12: 1 | H12: =IF(OR(E12="",F12=""),"",ROUND(MOD(F12-E12,1)*24-N(G12),2)) | I12: =IF(H12="","",ROUND(MAX(0,H12-8),2)) | J12: =IF(OR(E12="",F12=""),"",ROUND(IF(MOD(F12,1)>=TIME(22,0,0),(MOD(F12,1)-TIME(22,0,0))*24,IF(MOD(F12,1)<TIME(6,0,0),(MOD(F12,1)+1-TIME(22,0,0))*24,0)),2)) | K12: =IF(H12="","",ROUND(IF(L12="휴일근로",MIN(H12,8)*1.5+MAX(0,H12-8)*2,I12*1.5)+N(J12)*0.5,2)) | L12: 정상
A13: 46042 | B13: =IF(A13="","",CHOOSE(WEEKDAY(A13,2),"월","화","수","목","금","토","일")) | C13: M001 | D13: =IFERROR(IF(C13="","",INDEX(직원명부!$B$5:$B$24,MATCH(C13,직원명부!$A$5:$A$24,0))),"사번 확인") | E13: 0.375 | F13: 0.75 | G13: 1 | H13: =IF(OR(E13="",F13=""),"",ROUND(MOD(F13-E13,1)*24-N(G13),2)) | I13: =IF(H13="","",ROUND(MAX(0,H13-8),2)) | J13: =IF(OR(E13="",F13=""),"",ROUND(IF(MOD(F13,1)>=TIME(22,0,0),(MOD(F13,1)-TIME(22,0,0))*24,IF(MOD(F13,1)<TIME(6,0,0),(MOD(F13,1)+1-TIME(22,0,0))*24,0)),2)) | K13: =IF(H13="","",ROUND(IF(L13="휴일근로",MIN(H13,8)*1.5+MAX(0,H13-8)*2,I13*1.5)+N(J13)*0.5,2)) | L13: 정상
A14: 46043 | B14: =IF(A14="","",CHOOSE(WEEKDAY(A14,2),"월","화","수","목","금","토","일")) | C14: M001 | D14: =IFERROR(IF(C14="","",INDEX(직원명부!$B$5:$B$24,MATCH(C14,직원명부!$A$5:$A$24,0))),"사번 확인") | E14: 0.375 | F14: 0.75 | G14: 1 | H14: =IF(OR(E14="",F14=""),"",ROUND(MOD(F14-E14,1)*24-N(G14),2)) | I14: =IF(H14="","",ROUND(MAX(0,H14-8),2)) | J14: =IF(OR(E14="",F14=""),"",ROUND(IF(MOD(F14,1)>=TIME(22,0,0),(MOD(F14,1)-TIME(22,0,0))*24,IF(MOD(F14,1)<TIME(6,0,0),(MOD(F14,1)+1-TIME(22,0,0))*24,0)),2)) | K14: =IF(H14="","",ROUND(IF(L14="휴일근로",MIN(H14,8)*1.5+MAX(0,H14-8)*2,I14*1.5)+N(J14)*0.5,2)) | L14: 정상
A15: 46044 | B15: =IF(A15="","",CHOOSE(WEEKDAY(A15,2),"월","화","수","목","금","토","일")) | C15: M001 | D15: =IFERROR(IF(C15="","",INDEX(직원명부!$B$5:$B$24,MATCH(C15,직원명부!$A$5:$A$24,0))),"사번 확인") | E15: 0.375 | F15: 0.75 | G15: 1 | H15: =IF(OR(E15="",F15=""),"",ROUND(MOD(F15-E15,1)*24-N(G15),2)) | I15: =IF(H15="","",ROUND(MAX(0,H15-8),2)) | J15: =IF(OR(E15="",F15=""),"",ROUND(IF(MOD(F15,1)>=TIME(22,0,0),(MOD(F15,1)-TIME(22,0,0))*24,IF(MOD(F15,1)<TIME(6,0,0),(MOD(F15,1)+1-TIME(22,0,0))*24,0)),2)) | K15: =IF(H15="","",ROUND(IF(L15="휴일근로",MIN(H15,8)*1.5+MAX(0,H15-8)*2,I15*1.5)+N(J15)*0.5,2)) | L15: 정상
A16: 46045 | B16: =IF(A16="","",CHOOSE(WEEKDAY(A16,2),"월","화","수","목","금","토","일")) | C16: M001 | D16: =IFERROR(IF(C16="","",INDEX(직원명부!$B$5:$B$24,MATCH(C16,직원명부!$A$5:$A$24,0))),"사번 확인") | E16: 0.375 | F16: 0.75 | G16: 1 | H16: =IF(OR(E16="",F16=""),"",ROUND(MOD(F16-E16,1)*24-N(G16),2)) | I16: =IF(H16="","",ROUND(MAX(0,H16-8),2)) | J16: =IF(OR(E16="",F16=""),"",ROUND(IF(MOD(F16,1)>=TIME(22,0,0),(MOD(F16,1)-TIME(22,0,0))*24,IF(MOD(F16,1)<TIME(6,0,0),(MOD(F16,1)+1-TIME(22,0,0))*24,0)),2)) | K16: =IF(H16="","",ROUND(IF(L16="휴일근로",MIN(H16,8)*1.5+MAX(0,H16-8)*2,I16*1.5)+N(J16)*0.5,2)) | L16: 정상
A17: 46046 | B17: =IF(A17="","",CHOOSE(WEEKDAY(A17,2),"월","화","수","목","금","토","일")) | C17: M001 | D17: =IFERROR(IF(C17="","",INDEX(직원명부!$B$5:$B$24,MATCH(C17,직원명부!$A$5:$A$24,0))),"사번 확인") | H17: =IF(OR(E17="",F17=""),"",ROUND(MOD(F17-E17,1)*24-N(G17),2)) | I17: =IF(H17="","",ROUND(MAX(0,H17-8),2)) | J17: =IF(OR(E17="",F17=""),"",ROUND(IF(MOD(F17,1)>=TIME(22,0,0),(MOD(F17,1)-TIME(22,0,0))*24,IF(MOD(F17,1)<TIME(6,0,0),(MOD(F17,1)+1-TIME(22,0,0))*24,0)),2)) | K17: =IF(H17="","",ROUND(IF(L17="휴일근로",MIN(H17,8)*1.5+MAX(0,H17-8)*2,I17*1.5)+N(J17)*0.5,2)) | N17: 주말
A18: 46047 | B18: =IF(A18="","",CHOOSE(WEEKDAY(A18,2),"월","화","수","목","금","토","일")) | C18: M001 | D18: =IFERROR(IF(C18="","",INDEX(직원명부!$B$5:$B$24,MATCH(C18,직원명부!$A$5:$A$24,0))),"사번 확인") | H18: =IF(OR(E18="",F18=""),"",ROUND(MOD(F18-E18,1)*24-N(G18),2)) | I18: =IF(H18="","",ROUND(MAX(0,H18-8),2)) | J18: =IF(OR(E18="",F18=""),"",ROUND(IF(MOD(F18,1)>=TIME(22,0,0),(MOD(F18,1)-TIME(22,0,0))*24,IF(MOD(F18,1)<TIME(6,0,0),(MOD(F18,1)+1-TIME(22,0,0))*24,0)),2)) | K18: =IF(H18="","",ROUND(IF(L18="휴일근로",MIN(H18,8)*1.5+MAX(0,H18-8)*2,I18*1.5)+N(J18)*0.5,2)) | N18: 주말
A19: 46048 | B19: =IF(A19="","",CHOOSE(WEEKDAY(A19,2),"월","화","수","목","금","토","일")) | C19: M001 | D19: =IFERROR(IF(C19="","",INDEX(직원명부!$B$5:$B$24,MATCH(C19,직원명부!$A$5:$A$24,0))),"사번 확인") | E19: 0.375 | F19: 0.75 | G19: 1 | H19: =IF(OR(E19="",F19=""),"",ROUND(MOD(F19-E19,1)*24-N(G19),2)) | I19: =IF(H19="","",ROUND(MAX(0,H19-8),2)) | J19: =IF(OR(E19="",F19=""),"",ROUND(IF(MOD(F19,1)>=TIME(22,0,0),(MOD(F19,1)-TIME(22,0,0))*24,IF(MOD(F19,1)<TIME(6,0,0),(MOD(F19,1)+1-TIME(22,0,0))*24,0)),2)) | K19: =IF(H19="","",ROUND(IF(L19="휴일근로",MIN(H19,8)*1.5+MAX(0,H19-8)*2,I19*1.5)+N(J19)*0.5,2)) | L19: 정상
A20: 46049 | B20: =IF(A20="","",CHOOSE(WEEKDAY(A20,2),"월","화","수","목","금","토","일")) | C20: M001 | D20: =IFERROR(IF(C20="","",INDEX(직원명부!$B$5:$B$24,MATCH(C20,직원명부!$A$5:$A$24,0))),"사번 확인") | E20: 0.375 | F20: 0.75 | G20: 1 | H20: =IF(OR(E20="",F20=""),"",ROUND(MOD(F20-E20,1)*24-N(G20),2)) | I20: =IF(H20="","",ROUND(MAX(0,H20-8),2)) | J20: =IF(OR(E20="",F20=""),"",ROUND(IF(MOD(F20,1)>=TIME(22,0,0),(MOD(F20,1)-TIME(22,0,0))*24,IF(MOD(F20,1)<TIME(6,0,0),(MOD(F20,1)+1-TIME(22,0,0))*24,0)),2)) | K20: =IF(H20="","",ROUND(IF(L20="휴일근로",MIN(H20,8)*1.5+MAX(0,H20-8)*2,I20*1.5)+N(J20)*0.5,2)) | L20: 정상
A21: 46050 | B21: =IF(A21="","",CHOOSE(WEEKDAY(A21,2),"월","화","수","목","금","토","일")) | C21: M001 | D21: =IFERROR(IF(C21="","",INDEX(직원명부!$B$5:$B$24,MATCH(C21,직원명부!$A$5:$A$24,0))),"사번 확인") | E21: 0.375 | F21: 0.75 | G21: 1 | H21: =IF(OR(E21="",F21=""),"",ROUND(MOD(F21-E21,1)*24-N(G21),2)) | I21: =IF(H21="","",ROUND(MAX(0,H21-8),2)) | J21: =IF(OR(E21="",F21=""),"",ROUND(IF(MOD(F21,1)>=TIME(22,0,0),(MOD(F21,1)-TIME(22,0,0))*24,IF(MOD(F21,1)<TIME(6,0,0),(MOD(F21,1)+1-TIME(22,0,0))*24,0)),2)) | K21: =IF(H21="","",ROUND(IF(L21="휴일근로",MIN(H21,8)*1.5+MAX(0,H21-8)*2,I21*1.5)+N(J21)*0.5,2)) | L21: 정상
A22: 46051 | B22: =IF(A22="","",CHOOSE(WEEKDAY(A22,2),"월","화","수","목","금","토","일")) | C22: M001 | D22: =IFERROR(IF(C22="","",INDEX(직원명부!$B$5:$B$24,MATCH(C22,직원명부!$A$5:$A$24,0))),"사번 확인") | E22: 0.375 | F22: 0.75 | G22: 1 | H22: =IF(OR(E22="",F22=""),"",ROUND(MOD(F22-E22,1)*24-N(G22),2)) | I22: =IF(H22="","",ROUND(MAX(0,H22-8),2)) | J22: =IF(OR(E22="",F22=""),"",ROUND(IF(MOD(F22,1)>=TIME(22,0,0),(MOD(F22,1)-TIME(22,0,0))*24,IF(MOD(F22,1)<TIME(6,0,0),(MOD(F22,1)+1-TIME(22,0,0))*24,0)),2)) | K22: =IF(H22="","",ROUND(IF(L22="휴일근로",MIN(H22,8)*1.5+MAX(0,H22-8)*2,I22*1.5)+N(J22)*0.5,2)) | L22: 정상
A23: 46052 | B23: =IF(A23="","",CHOOSE(WEEKDAY(A23,2),"월","화","수","목","금","토","일")) | C23: M001 | D23: =IFERROR(IF(C23="","",INDEX(직원명부!$B$5:$B$24,MATCH(C23,직원명부!$A$5:$A$24,0))),"사번 확인") | E23: 0.375 | F23: 0.75 | G23: 1 | H23: =IF(OR(E23="",F23=""),"",ROUND(MOD(F23-E23,1)*24-N(G23),2)) | I23: =IF(H23="","",ROUND(MAX(0,H23-8),2)) | J23: =IF(OR(E23="",F23=""),"",ROUND(IF(MOD(F23,1)>=TIME(22,0,0),(MOD(F23,1)-TIME(22,0,0))*24,IF(MOD(F23,1)<TIME(6,0,0),(MOD(F23,1)+1-TIME(22,0,0))*24,0)),2)) | K23: =IF(H23="","",ROUND(IF(L23="휴일근로",MIN(H23,8)*1.5+MAX(0,H23-8)*2,I23*1.5)+N(J23)*0.5,2)) | L23: 정상
A24: 46053 | B24: =IF(A24="","",CHOOSE(WEEKDAY(A24,2),"월","화","수","목","금","토","일")) | C24: M001 | D24: =IFERROR(IF(C24="","",INDEX(직원명부!$B$5:$B$24,MATCH(C24,직원명부!$A$5:$A$24,0))),"사번 확인") | H24: =IF(OR(E24="",F24=""),"",ROUND(MOD(F24-E24,1)*24-N(G24),2)) | I24: =IF(H24="","",ROUND(MAX(0,H24-8),2)) | J24: =IF(OR(E24="",F24=""),"",ROUND(IF(MOD(F24,1)>=TIME(22,0,0),(MOD(F24,1)-TIME(22,0,0))*24,IF(MOD(F24,1)<TIME(6,0,0),(MOD(F24,1)+1-TIME(22,0,0))*24,0)),2)) | K24: =IF(H24="","",ROUND(IF(L24="휴일근로",MIN(H24,8)*1.5+MAX(0,H24-8)*2,I24*1.5)+N(J24)*0.5,2)) | N24: 주말
A25: 46054 | B25: =IF(A25="","",CHOOSE(WEEKDAY(A25,2),"월","화","수","목","금","토","일")) | C25: M001 | D25: =IFERROR(IF(C25="","",INDEX(직원명부!$B$5:$B$24,MATCH(C25,직원명부!$A$5:$A$24,0))),"사번 확인") | H25: =IF(OR(E25="",F25=""),"",ROUND(MOD(F25-E25,1)*24-N(G25),2)) | I25: =IF(H25="","",ROUND(MAX(0,H25-8),2)) | J25: =IF(OR(E25="",F25=""),"",ROUND(IF(MOD(F25,1)>=TIME(22,0,0),(MOD(F25,1)-TIME(22,0,0))*24,IF(MOD(F25,1)<TIME(6,0,0),(MOD(F25,1)+1-TIME(22,0,0))*24,0)),2)) | K25: =IF(H25="","",ROUND(IF(L25="휴일근로",MIN(H25,8)*1.5+MAX(0,H25-8)*2,I25*1.5)+N(J25)*0.5,2)) | N25: 주말
A26: 46055 | B26: =IF(A26="","",CHOOSE(WEEKDAY(A26,2),"월","화","수","목","금","토","일")) | C26: M001 | D26: =IFERROR(IF(C26="","",INDEX(직원명부!$B$5:$B$24,MATCH(C26,직원명부!$A$5:$A$24,0))),"사번 확인") | E26: 0.375 | F26: 0.75 | G26: 1 | H26: =IF(OR(E26="",F26=""),"",ROUND(MOD(F26-E26,1)*24-N(G26),2)) | I26: =IF(H26="","",ROUND(MAX(0,H26-8),2)) | J26: =IF(OR(E26="",F26=""),"",ROUND(IF(MOD(F26,1)>=TIME(22,0,0),(MOD(F26,1)-TIME(22,0,0))*24,IF(MOD(F26,1)<TIME(6,0,0),(MOD(F26,1)+1-TIME(22,0,0))*24,0)),2)) | K26: =IF(H26="","",ROUND(IF(L26="휴일근로",MIN(H26,8)*1.5+MAX(0,H26-8)*2,I26*1.5)+N(J26)*0.5,2)) | L26: 정상
A27: 46056 | B27: =IF(A27="","",CHOOSE(WEEKDAY(A27,2),"월","화","수","목","금","토","일")) | C27: M001 | D27: =IFERROR(IF(C27="","",INDEX(직원명부!$B$5:$B$24,MATCH(C27,직원명부!$A$5:$A$24,0))),"사번 확인") | E27: 0.375 | F27: 0.75 | G27: 1 | H27: =IF(OR(E27="",F27=""),"",ROUND(MOD(F27-E27,1)*24-N(G27),2)) | I27: =IF(H27="","",ROUND(MAX(0,H27-8),2)) | J27: =IF(OR(E27="",F27=""),"",ROUND(IF(MOD(F27,1)>=TIME(22,0,0),(MOD(F27,1)-TIME(22,0,0))*24,IF(MOD(F27,1)<TIME(6,0,0),(MOD(F27,1)+1-TIME(22,0,0))*24,0)),2)) | K27: =IF(H27="","",ROUND(IF(L27="휴일근로",MIN(H27,8)*1.5+MAX(0,H27-8)*2,I27*1.5)+N(J27)*0.5,2)) | L27: 정상
A28: 46057 | B28: =IF(A28="","",CHOOSE(WEEKDAY(A28,2),"월","화","수","목","금","토","일")) | C28: M001 | D28: =IFERROR(IF(C28="","",INDEX(직원명부!$B$5:$B$24,MATCH(C28,직원명부!$A$5:$A$24,0))),"사번 확인") | E28: 0.375 | F28: 0.75 | G28: 1 | H28: =IF(OR(E28="",F28=""),"",ROUND(MOD(F28-E28,1)*24-N(G28),2)) | I28: =IF(H28="","",ROUND(MAX(0,H28-8),2)) | J28: =IF(OR(E28="",F28=""),"",ROUND(IF(MOD(F28,1)>=TIME(22,0,0),(MOD(F28,1)-TIME(22,0,0))*24,IF(MOD(F28,1)<TIME(6,0,0),(MOD(F28,1)+1-TIME(22,0,0))*24,0)),2)) | K28: =IF(H28="","",ROUND(IF(L28="휴일근로",MIN(H28,8)*1.5+MAX(0,H28-8)*2,I28*1.5)+N(J28)*0.5,2)) | L28: 정상
A29: 46058 | B29: =IF(A29="","",CHOOSE(WEEKDAY(A29,2),"월","화","수","목","금","토","일")) | C29: M001 | D29: =IFERROR(IF(C29="","",INDEX(직원명부!$B$5:$B$24,MATCH(C29,직원명부!$A$5:$A$24,0))),"사번 확인") | E29: 0.375 | F29: 0.75 | G29: 1 | H29: =IF(OR(E29="",F29=""),"",ROUND(MOD(F29-E29,1)*24-N(G29),2)) | I29: =IF(H29="","",ROUND(MAX(0,H29-8),2)) | J29: =IF(OR(E29="",F29=""),"",ROUND(IF(MOD(F29,1)>=TIME(22,0,0),(MOD(F29,1)-TIME(22,0,0))*24,IF(MOD(F29,1)<TIME(6,0,0),(MOD(F29,1)+1-TIME(22,0,0))*24,0)),2)) | K29: =IF(H29="","",ROUND(IF(L29="휴일근로",MIN(H29,8)*1.5+MAX(0,H29-8)*2,I29*1.5)+N(J29)*0.5,2)) | L29: 정상
A30: 46059 | B30: =IF(A30="","",CHOOSE(WEEKDAY(A30,2),"월","화","수","목","금","토","일")) | C30: M001 | D30: =IFERROR(IF(C30="","",INDEX(직원명부!$B$5:$B$24,MATCH(C30,직원명부!$A$5:$A$24,0))),"사번 확인") | E30: 0.375 | F30: 0.75 | G30: 1 | H30: =IF(OR(E30="",F30=""),"",ROUND(MOD(F30-E30,1)*24-N(G30),2)) | I30: =IF(H30="","",ROUND(MAX(0,H30-8),2)) | J30: =IF(OR(E30="",F30=""),"",ROUND(IF(MOD(F30,1)>=TIME(22,0,0),(MOD(F30,1)-TIME(22,0,0))*24,IF(MOD(F30,1)<TIME(6,0,0),(MOD(F30,1)+1-TIME(22,0,0))*24,0)),2)) | K30: =IF(H30="","",ROUND(IF(L30="휴일근로",MIN(H30,8)*1.5+MAX(0,H30-8)*2,I30*1.5)+N(J30)*0.5,2)) | L30: 정상
A31: 46060 | B31: =IF(A31="","",CHOOSE(WEEKDAY(A31,2),"월","화","수","목","금","토","일")) | C31: M001 | D31: =IFERROR(IF(C31="","",INDEX(직원명부!$B$5:$B$24,MATCH(C31,직원명부!$A$5:$A$24,0))),"사번 확인") | H31: =IF(OR(E31="",F31=""),"",ROUND(MOD(F31-E31,1)*24-N(G31),2)) | I31: =IF(H31="","",ROUND(MAX(0,H31-8),2)) | J31: =IF(OR(E31="",F31=""),"",ROUND(IF(MOD(F31,1)>=TIME(22,0,0),(MOD(F31,1)-TIME(22,0,0))*24,IF(MOD(F31,1)<TIME(6,0,0),(MOD(F31,1)+1-TIME(22,0,0))*24,0)),2)) | K31: =IF(H31="","",ROUND(IF(L31="휴일근로",MIN(H31,8)*1.5+MAX(0,H31-8)*2,I31*1.5)+N(J31)*0.5,2)) | N31: 주말
A32: 46061 | B32: =IF(A32="","",CHOOSE(WEEKDAY(A32,2),"월","화","수","목","금","토","일")) | C32: M001 | D32: =IFERROR(IF(C32="","",INDEX(직원명부!$B$5:$B$24,MATCH(C32,직원명부!$A$5:$A$24,0))),"사번 확인") | H32: =IF(OR(E32="",F32=""),"",ROUND(MOD(F32-E32,1)*24-N(G32),2)) | I32: =IF(H32="","",ROUND(MAX(0,H32-8),2)) | J32: =IF(OR(E32="",F32=""),"",ROUND(IF(MOD(F32,1)>=TIME(22,0,0),(MOD(F32,1)-TIME(22,0,0))*24,IF(MOD(F32,1)<TIME(6,0,0),(MOD(F32,1)+1-TIME(22,0,0))*24,0)),2)) | K32: =IF(H32="","",ROUND(IF(L32="휴일근로",MIN(H32,8)*1.5+MAX(0,H32-8)*2,I32*1.5)+N(J32)*0.5,2)) | N32: 주말
A33: 46062 | B33: =IF(A33="","",CHOOSE(WEEKDAY(A33,2),"월","화","수","목","금","토","일")) | C33: M001 | D33: =IFERROR(IF(C33="","",INDEX(직원명부!$B$5:$B$24,MATCH(C33,직원명부!$A$5:$A$24,0))),"사번 확인") | E33: 0.375 | F33: 0.75 | G33: 1 | H33: =IF(OR(E33="",F33=""),"",ROUND(MOD(F33-E33,1)*24-N(G33),2)) | I33: =IF(H33="","",ROUND(MAX(0,H33-8),2)) | J33: =IF(OR(E33="",F33=""),"",ROUND(IF(MOD(F33,1)>=TIME(22,0,0),(MOD(F33,1)-TIME(22,0,0))*24,IF(MOD(F33,1)<TIME(6,0,0),(MOD(F33,1)+1-TIME(22,0,0))*24,0)),2)) | K33: =IF(H33="","",ROUND(IF(L33="휴일근로",MIN(H33,8)*1.5+MAX(0,H33-8)*2,I33*1.5)+N(J33)*0.5,2)) | L33: 정상
A34: 46063 | B34: =IF(A34="","",CHOOSE(WEEKDAY(A34,2),"월","화","수","목","금","토","일")) | C34: M001 | D34: =IFERROR(IF(C34="","",INDEX(직원명부!$B$5:$B$24,MATCH(C34,직원명부!$A$5:$A$24,0))),"사번 확인") | E34: 0.375 | F34: 0.75 | G34: 1 | H34: =IF(OR(E34="",F34=""),"",ROUND(MOD(F34-E34,1)*24-N(G34),2)) | I34: =IF(H34="","",ROUND(MAX(0,H34-8),2)) | J34: =IF(OR(E34="",F34=""),"",ROUND(IF(MOD(F34,1)>=TIME(22,0,0),(MOD(F34,1)-TIME(22,0,0))*24,IF(MOD(F34,1)<TIME(6,0,0),(MOD(F34,1)+1-TIME(22,0,0))*24,0)),2)) | K34: =IF(H34="","",ROUND(IF(L34="휴일근로",MIN(H34,8)*1.5+MAX(0,H34-8)*2,I34*1.5)+N(J34)*0.5,2)) | L34: 정상
A35: 46064 | B35: =IF(A35="","",CHOOSE(WEEKDAY(A35,2),"월","화","수","목","금","토","일")) | C35: M001 | D35: =IFERROR(IF(C35="","",INDEX(직원명부!$B$5:$B$24,MATCH(C35,직원명부!$A$5:$A$24,0))),"사번 확인") | E35: 0.375 | F35: 0.75 | G35: 1 | H35: =IF(OR(E35="",F35=""),"",ROUND(MOD(F35-E35,1)*24-N(G35),2)) | I35: =IF(H35="","",ROUND(MAX(0,H35-8),2)) | J35: =IF(OR(E35="",F35=""),"",ROUND(IF(MOD(F35,1)>=TIME(22,0,0),(MOD(F35,1)-TIME(22,0,0))*24,IF(MOD(F35,1)<TIME(6,0,0),(MOD(F35,1)+1-TIME(22,0,0))*24,0)),2)) | K35: =IF(H35="","",ROUND(IF(L35="휴일근로",MIN(H35,8)*1.5+MAX(0,H35-8)*2,I35*1.5)+N(J35)*0.5,2)) | L35: 정상
A36: 46065 | B36: =IF(A36="","",CHOOSE(WEEKDAY(A36,2),"월","화","수","목","금","토","일")) | C36: M001 | D36: =IFERROR(IF(C36="","",INDEX(직원명부!$B$5:$B$24,MATCH(C36,직원명부!$A$5:$A$24,0))),"사번 확인") | E36: 0.375 | F36: 0.75 | G36: 1 | H36: =IF(OR(E36="",F36=""),"",ROUND(MOD(F36-E36,1)*24-N(G36),2)) | I36: =IF(H36="","",ROUND(MAX(0,H36-8),2)) | J36: =IF(OR(E36="",F36=""),"",ROUND(IF(MOD(F36,1)>=TIME(22,0,0),(MOD(F36,1)-TIME(22,0,0))*24,IF(MOD(F36,1)<TIME(6,0,0),(MOD(F36,1)+1-TIME(22,0,0))*24,0)),2)) | K36: =IF(H36="","",ROUND(IF(L36="휴일근로",MIN(H36,8)*1.5+MAX(0,H36-8)*2,I36*1.5)+N(J36)*0.5,2)) | L36: 정상
A37: 46066 | B37: =IF(A37="","",CHOOSE(WEEKDAY(A37,2),"월","화","수","목","금","토","일")) | C37: M001 | D37: =IFERROR(IF(C37="","",INDEX(직원명부!$B$5:$B$24,MATCH(C37,직원명부!$A$5:$A$24,0))),"사번 확인") | E37: 0.375 | F37: 0.75 | G37: 1 | H37: =IF(OR(E37="",F37=""),"",ROUND(MOD(F37-E37,1)*24-N(G37),2)) | I37: =IF(H37="","",ROUND(MAX(0,H37-8),2)) | J37: =IF(OR(E37="",F37=""),"",ROUND(IF(MOD(F37,1)>=TIME(22,0,0),(MOD(F37,1)-TIME(22,0,0))*24,IF(MOD(F37,1)<TIME(6,0,0),(MOD(F37,1)+1-TIME(22,0,0))*24,0)),2)) | K37: =IF(H37="","",ROUND(IF(L37="휴일근로",MIN(H37,8)*1.5+MAX(0,H37-8)*2,I37*1.5)+N(J37)*0.5,2)) | L37: 정상
A38: 46067 | B38: =IF(A38="","",CHOOSE(WEEKDAY(A38,2),"월","화","수","목","금","토","일")) | C38: M001 | D38: =IFERROR(IF(C38="","",INDEX(직원명부!$B$5:$B$24,MATCH(C38,직원명부!$A$5:$A$24,0))),"사번 확인") | H38: =IF(OR(E38="",F38=""),"",ROUND(MOD(F38-E38,1)*24-N(G38),2)) | I38: =IF(H38="","",ROUND(MAX(0,H38-8),2)) | J38: =IF(OR(E38="",F38=""),"",ROUND(IF(MOD(F38,1)>=TIME(22,0,0),(MOD(F38,1)-TIME(22,0,0))*24,IF(MOD(F38,1)<TIME(6,0,0),(MOD(F38,1)+1-TIME(22,0,0))*24,0)),2)) | K38: =IF(H38="","",ROUND(IF(L38="휴일근로",MIN(H38,8)*1.5+MAX(0,H38-8)*2,I38*1.5)+N(J38)*0.5,2)) | N38: 주말
A39: 46068 | B39: =IF(A39="","",CHOOSE(WEEKDAY(A39,2),"월","화","수","목","금","토","일")) | C39: M001 | D39: =IFERROR(IF(C39="","",INDEX(직원명부!$B$5:$B$24,MATCH(C39,직원명부!$A$5:$A$24,0))),"사번 확인") | H39: =IF(OR(E39="",F39=""),"",ROUND(MOD(F39-E39,1)*24-N(G39),2)) | I39: =IF(H39="","",ROUND(MAX(0,H39-8),2)) | J39: =IF(OR(E39="",F39=""),"",ROUND(IF(MOD(F39,1)>=TIME(22,0,0),(MOD(F39,1)-TIME(22,0,0))*24,IF(MOD(F39,1)<TIME(6,0,0),(MOD(F39,1)+1-TIME(22,0,0))*24,0)),2)) | K39: =IF(H39="","",ROUND(IF(L39="휴일근로",MIN(H39,8)*1.5+MAX(0,H39-8)*2,I39*1.5)+N(J39)*0.5,2)) | N39: 주말
A40: 46069 | B40: =IF(A40="","",CHOOSE(WEEKDAY(A40,2),"월","화","수","목","금","토","일")) | C40: M001 | D40: =IFERROR(IF(C40="","",INDEX(직원명부!$B$5:$B$24,MATCH(C40,직원명부!$A$5:$A$24,0))),"사번 확인") | H40: =IF(OR(E40="",F40=""),"",ROUND(MOD(F40-E40,1)*24-N(G40),2)) | I40: =IF(H40="","",ROUND(MAX(0,H40-8),2)) | J40: =IF(OR(E40="",F40=""),"",ROUND(IF(MOD(F40,1)>=TIME(22,0,0),(MOD(F40,1)-TIME(22,0,0))*24,IF(MOD(F40,1)<TIME(6,0,0),(MOD(F40,1)+1-TIME(22,0,0))*24,0)),2)) | K40: =IF(H40="","",ROUND(IF(L40="휴일근로",MIN(H40,8)*1.5+MAX(0,H40-8)*2,I40*1.5)+N(J40)*0.5,2)) | N40: 설날 연휴
...

Sheet 월별집계
A1: 월별집계
A2: 조회할 달의 1일 날짜만 바꾸면 그 달 실적이 직원별로 자동 집계됩니다.
A3: 조회 월 | B3: 46266 | C3: ← 반드시 해당 월 1일 날짜로 넣으세요. (예: 2026-05-01)
A4: 사번 | B4: 성명 | C4: 재직상태 | D4: 근무일수 | E4: 총 근무시간 | F4: 연장시간 | G4: 지각 | H4: 조퇴 | I4: 결근 | J4: 연차사용 | K4: 기타휴가
A5: =IF(직원명부!A5="","",직원명부!A5) | B5: =IF(직원명부!B5="","",직원명부!B5) | C5: =IF(직원명부!F5="","",직원명부!F5) | D5: =IF($A5="","",COUNTIFS(근태기록!$C$5:$C$2004,$A5,근태기록!$A$5:$A$2004,">="&$B$3,근태기록!$A$5:$A$2004,"<="&EOMONTH($B$3,0),근태기록!$H$5:$H$2004,">0")) | E5: =IF($A5="","",SUMIFS(근태기록!$H$5:$H$2004,근태기록!$C$5:$C$2004,$A5,근태기록!$A$5:$A$2004,">="&$B$3,근태기록!$A$5:$A$2004,"<="&EOMONTH($B$3,0))) | F5: =IF($A5="","",SUMIFS(근태기록!$I$5:$I$2004,근태기록!$C$5:$C$2004,$A5,근태기록!$A$5:$A$2004,">="&$B$3,근태기록!$A$5:$A$2004,"<="&EOMONTH($B$3,0))) | G5: =IF($A5="","",COUNTIFS(근태기록!$C$5:$C$2004,$A5,근태기록!$A$5:$A$2004,">="&$B$3,근태기록!$A$5:$A$2004,"<="&EOMONTH($B$3,0),근태기록!$L$5:$L$2004,"지각")) | H5: =IF($A5="","",COUNTIFS(근태기록!$C$5:$C$2004,$A5,근태기록!$A$5:$A$2004,">="&$B$3,근태기록!$A$5:$A$2004,"<="&EOMONTH($B$3,0),근태기록!$L$5:$L$2004,"조퇴")) | I5: =IF($A5="","",COUNTIFS(근태기록!$C$5:$C$2004,$A5,근태기록!$A$5:$A$2004,">="&$B$3,근태기록!$A$5:$A$2004,"<="&EOMONTH($B$3,0),근태기록!$L$5:$L$2004,"결근")) | J5: =IF($A5="","",SUMIFS(휴가대장!$F$5:$F$504,휴가대장!$B$5:$B$504,$A5,휴가대장!$E$5:$E$504,"연차",휴가대장!$D$5:$D$504,">="&$B$3,휴가대장!$D$5:$D$504,"<="&EOMONTH($B$3,0))) | K5: =IF($A5="","",SUMIFS(휴가대장!$F$5:$F$504,휴가대장!$B$5:$B$504,$A5,휴가대장!$D$5:$D$504,">="&$B$3,휴가대장!$D$5:$D$504,"<="&EOMONTH($B$3,0))-SUMIFS(휴가대장!$F$5:$F$504,휴가대장!$B$5:$B$504,$A5,휴가대장!$E$5:$E$504,"연차",휴가대장!$D$5:$D$504,">="&$B$3,휴가대장!$D$5:$D$504,"<="&EOMONTH($B$3,0)))
A6: =IF(직원명부!A6="","",직원명부!A6) | B6: =IF(직원명부!B6="","",직원명부!B6) | C6: =IF(직원명부!F6="","",직원명부!F6) | D6: =IF($A6="","",COUNTIFS(근태기록!$C$5:$C$2004,$A6,근태기록!$A$5:$A$2004,">="&$B$3,근태기록!$A$5:$A$2004,"<="&EOMONTH($B$3,0),근태기록!$H$5:$H$2004,">0")) | E6: =IF($A6="","",SUMIFS(근태기록!$H$5:$H$2004,근태기록!$C$5:$C$2004,$A6,근태기록!$A$5:$A$2004,">="&$B$3,근태기록!$A$5:$A$2004,"<="&EOMONTH($B$3,0))) | F6: =IF($A6="","",SUMIFS(근태기록!$I$5:$I$2004,근태기록!$C$5:$C$2004,$A6,근태기록!$A$5:$A$2004,">="&$B$3,근태기록!$A$5:$A$2004,"<="&EOMONTH($B$3,0))) | G6: =IF($A6="","",COUNTIFS(근태기록!$C$5:$C$2004,$A6,근태기록!$A$5:$A$2004,">="&$B$3,근태기록!$A$5:$A$2004,"<="&EOMONTH($B$3,0),근태기록!$L$5:$L$2004,"지각")) | H6: =IF($A6="","",COUNTIFS(근태기록!$C$5:$C$2004,$A6,근태기록!$A$5:$A$2004,">="&$B$3,근태기록!$A$5:$A$2004,"<="&EOMONTH($B$3,0),근태기록!$L$5:$L$2004,"조퇴")) | I6: =IF($A6="","",COUNTIFS(근태기록!$C$5:$C$2004,$A6,근태기록!$A$5:$A$2004,">="&$B$3,근태기록!$A$5:$A$2004,"<="&EOMONTH($B$3,0),근태기록!$L$5:$L$2004,"결근")) | J6: =IF($A6="","",SUMIFS(휴가대장!$F$5:$F$504,휴가대장!$B$5:$B$504,$A6,휴가대장!$E$5:$E$504,"연차",휴가대장!$D$5:$D$504,">="&$B$3,휴가대장!$D$5:$D$504,"<="&EOMONTH($B$3,0))) | K6: =IF($A6="","",SUMIFS(휴가대장!$F$5:$F$504,휴가대장!$B$5:$B$504,$A6,휴가대장!$D$5:$D$504,">="&$B$3,휴가대장!$D$5:$D$504,"<="&EOMONTH($B$3,0))-SUMIFS(휴가대장!$F$5:$F$504,휴가대장!$B$5:$B$504,$A6,휴가대장!$E$5:$E$504,"연차",휴가대장!$D$5:$D$504,">="&$B$3,휴가대장!$D$5:$D$504,"<="&EOMONTH($B$3,0)))
A7: =IF(직원명부!A7="","",직원명부!A7) | B7: =IF(직원명부!B7="","",직원명부!B7) | C7: =IF(직원명부!F7="","",직원명부!F7) | D7: =IF($A7="","",COUNTIFS(근태기록!$C$5:$C$2004,$A7,근태기록!$A$5:$A$2004,">="&$B$3,근태기록!$A$5:$A$2004,"<="&EOMONTH($B$3,0),근태기록!$H$5:$H$2004,">0")) | E7: =IF($A7="","",SUMIFS(근태기록!$H$5:$H$2004,근태기록!$C$5:$C$2004,$A7,근태기록!$A$5:$A$2004,">="&$B$3,근태기록!$A$5:$A$2004,"<="&EOMONTH($B$3,0))) | F7: =IF($A7="","",SUMIFS(근태기록!$I$5:$I$2004,근태기록!$C$5:$C$2004,$A7,근태기록!$A$5:$A$2004,">="&$B$3,근태기록!$A$5:$A$2004,"<="&EOMONTH($B$3,0))) | G7: =IF($A7="","",COUNTIFS(근태기록!$C$5:$C$2004,$A7,근태기록!$A$5:$A$2004,">="&$B$3,근태기록!$A$5:$A$2004,"<="&EOMONTH($B$3,0),근태기록!$L$5:$L$2004,"지각")) | H7: =IF($A7="","",COUNTIFS(근태기록!$C$5:$C$2004,$A7,근태기록!$A$5:$A$2004,">="&$B$3,근태기록!$A$5:$A$2004,"<="&EOMONTH($B$3,0),근태기록!$L$5:$L$2004,"조퇴")) | I7: =IF($A7="","",COUNTIFS(근태기록!$C$5:$C$2004,$A7,근태기록!$A$5:$A$2004,">="&$B$3,근태기록!$A$5:$A$2004,"<="&EOMONTH($B$3,0),근태기록!$L$5:$L$2004,"결근")) | J7: =IF($A7="","",SUMIFS(휴가대장!$F$5:$F$504,휴가대장!$B$5:$B$504,$A7,휴가대장!$E$5:$E$504,"연차",휴가대장!$D$5:$D$504,">="&$B$3,휴가대장!$D$5:$D$504,"<="&EOMONTH($B$3,0))) | K7: =IF($A7="","",SUMIFS(휴가대장!$F$5:$F$504,휴가대장!$B$5:$B$504,$A7,휴가대장!$D$5:$D$504,">="&$B$3,휴가대장!$D$5:$D$504,"<="&EOMONTH($B$3,0))-SUMIFS(휴가대장!$F$5:$F$504,휴가대장!$B$5:$B$504,$A7,휴가대장!$E$5:$E$504,"연차",휴가대장!$D$5:$D$504,">="&$B$3,휴가대장!$D$5:$D$504,"<="&EOMONTH($B$3,0)))
A8: =IF(직원명부!A8="","",직원명부!A8) | B8: =IF(직원명부!B8="","",직원명부!B8) | C8: =IF(직원명부!F8="","",직원명부!F8) | D8: =IF($A8="","",COUNTIFS(근태기록!$C$5:$C$2004,$A8,근태기록!$A$5:$A$2004,">="&$B$3,근태기록!$A$5:$A$2004,"<="&EOMONTH($B$3,0),근태기록!$H$5:$H$2004,">0")) | E8: =IF($A8="","",SUMIFS(근태기록!$H$5:$H$2004,근태기록!$C$5:$C$2004,$A8,근태기록!$A$5:$A$2004,">="&$B$3,근태기록!$A$5:$A$2004,"<="&EOMONTH($B$3,0))) | F8: =IF($A8="","",SUMIFS(근태기록!$I$5:$I$2004,근태기록!$C$5:$C$2004,$A8,근태기록!$A$5:$A$2004,">="&$B$3,근태기록!$A$5:$A$2004,"<="&EOMONTH($B$3,0))) | G8: =IF($A8="","",COUNTIFS(근태기록!$C$5:$C$2004,$A8,근태기록!$A$5:$A$2004,">="&$B$3,근태기록!$A$5:$A$2004,"<="&EOMONTH($B$3,0),근태기록!$L$5:$L$2004,"지각")) | H8: =IF($A8="","",COUNTIFS(근태기록!$C$5:$C$2004,$A8,근태기록!$A$5:$A$2004,">="&$B$3,근태기록!$A$5:$A$2004,"<="&EOMONTH($B$3,0),근태기록!$L$5:$L$2004,"조퇴")) | I8: =IF($A8="","",COUNTIFS(근태기록!$C$5:$C$2004,$A8,근태기록!$A$5:$A$2004,">="&$B$3,근태기록!$A$5:$A$2004,"<="&EOMONTH($B$3,0),근태기록!$L$5:$L$2004,"결근")) | J8: =IF($A8="","",SUMIFS(휴가대장!$F$5:$F$504,휴가대장!$B$5:$B$504,$A8,휴가대장!$E$5:$E$504,"연차",휴가대장!$D$5:$D$504,">="&$B$3,휴가대장!$D$5:$D$504,"<="&EOMONTH($B$3,0))) | K8: =IF($A8="","",SUMIFS(휴가대장!$F$5:$F$504,휴가대장!$B$5:$B$504,$A8,휴가대장!$D$5:$D$504,">="&$B$3,휴가대장!$D$5:$D$504,"<="&EOMONTH($B$3,0))-SUMIFS(휴가대장!$F$5:$F$504,휴가대장!$B$5:$B$504,$A8,휴가대장!$E$5:$E$504,"연차",휴가대장!$D$5:$D$504,">="&$B$3,휴가대장!$D$5:$D$504,"<="&EOMONTH($B$3,0)))
A9: =IF(직원명부!A9="","",직원명부!A9) | B9: =IF(직원명부!B9="","",직원명부!B9) | C9: =IF(직원명부!F9="","",직원명부!F9) | D9: =IF($A9="","",COUNTIFS(근태기록!$C$5:$C$2004,$A9,근태기록!$A$5:$A$2004,">="&$B$3,근태기록!$A$5:$A$2004,"<="&EOMONTH($B$3,0),근태기록!$H$5:$H$2004,">0")) | E9: =IF($A9="","",SUMIFS(근태기록!$H$5:$H$2004,근태기록!$C$5:$C$2004,$A9,근태기록!$A$5:$A$2004,">="&$B$3,근태기록!$A$5:$A$2004,"<="&EOMONTH($B$3,0))) | F9: =IF($A9="","",SUMIFS(근태기록!$I$5:$I$2004,근태기록!$C$5:$C$2004,$A9,근태기록!$A$5:$A$2004,">="&$B$3,근태기록!$A$5:$A$2004,"<="&EOMONTH($B$3,0))) | G9: =IF($A9="","",COUNTIFS(근태기록!$C$5:$C$2004,$A9,근태기록!$A$5:$A$2004,">="&$B$3,근태기록!$A$5:$A$2004,"<="&EOMONTH($B$3,0),근태기록!$L$5:$L$2004,"지각")) | H9: =IF($A9="","",COUNTIFS(근태기록!$C$5:$C$2004,$A9,근태기록!$A$5:$A$2004,">="&$B$3,근태기록!$A$5:$A$2004,"<="&EOMONTH($B$3,0),근태기록!$L$5:$L$2004,"조퇴")) | I9: =IF($A9="","",COUNTIFS(근태기록!$C$5:$C$2004,$A9,근태기록!$A$5:$A$2004,">="&$B$3,근태기록!$A$5:$A$2004,"<="&EOMONTH($B$3,0),근태기록!$L$5:$L$2004,"결근")) | J9: =IF($A9="","",SUMIFS(휴가대장!$F$5:$F$504,휴가대장!$B$5:$B$504,$A9,휴가대장!$E$5:$E$504,"연차",휴가대장!$D$5:$D$504,">="&$B$3,휴가대장!$D$5:$D$504,"<="&EOMONTH($B$3,0))) | K9: =IF($A9="","",SUMIFS(휴가대장!$F$5:$F$504,휴가대장!$B$5:$B$504,$A9,휴가대장!$D$5:$D$504,">="&$B$3,휴가대장!$D$5:$D$504,"<="&EOMONTH($B$3,0))-SUMIFS(휴가대장!$F$5:$F$504,휴가대장!$B$5:$B$504,$A9,휴가대장!$E$5:$E$504,"연차",휴가대장!$D$5:$D$504,">="&$B$3,휴가대장!$D$5:$D$504,"<="&EOMONTH($B$3,0)))
A10: =IF(직원명부!A10="","",직원명부!A10) | B10: =IF(직원명부!B10="","",직원명부!B10) | C10: =IF(직원명부!F10="","",직원명부!F10) | D10: =IF($A10="","",COUNTIFS(근태기록!$C$5:$C$2004,$A10,근태기록!$A$5:$A$2004,">="&$B$3,근태기록!$A$5:$A$2004,"<="&EOMONTH($B$3,0),근태기록!$H$5:$H$2004,">0")) | E10: =IF($A10="","",SUMIFS(근태기록!$H$5:$H$2004,근태기록!$C$5:$C$2004,$A10,근태기록!$A$5:$A$2004,">="&$B$3,근태기록!$A$5:$A$2004,"<="&EOMONTH($B$3,0))) | F10: =IF($A10="","",SUMIFS(근태기록!$I$5:$I$2004,근태기록!$C$5:$C$2004,$A10,근태기록!$A$5:$A$2004,">="&$B$3,근태기록!$A$5:$A$2004,"<="&EOMONTH($B$3,0))) | G10: =IF($A10="","",COUNTIFS(근태기록!$C$5:$C$2004,$A10,근태기록!$A$5:$A$2004,">="&$B$3,근태기록!$A$5:$A$2004,"<="&EOMONTH($B$3,0),근태기록!$L$5:$L$2004,"지각")) | H10: =IF($A10="","",COUNTIFS(근태기록!$C$5:$C$2004,$A10,근태기록!$A$5:$A$2004,">="&$B$3,근태기록!$A$5:$A$2004,"<="&EOMONTH($B$3,0),근태기록!$L$5:$L$2004,"조퇴")) | I10: =IF($A10="","",COUNTIFS(근태기록!$C$5:$C$2004,$A10,근태기록!$A$5:$A$2004,">="&$B$3,근태기록!$A$5:$A$2004,"<="&EOMONTH($B$3,0),근태기록!$L$5:$L$2004,"결근")) | J10: =IF($A10="","",SUMIFS(휴가대장!$F$5:$F$504,휴가대장!$B$5:$B$504,$A10,휴가대장!$E$5:$E$504,"연차",휴가대장!$D$5:$D$504,">="&$B$3,휴가대장!$D$5:$D$504,"<="&EOMONTH($B$3,0))) | K10: =IF($A10="","",SUMIFS(휴가대장!$F$5:$F$504,휴가대장!$B$5:$B$504,$A10,휴가대장!$D$5:$D$504,">="&$B$3,휴가대장!$D$5:$D$504,"<="&EOMONTH($B$3,0))-SUMIFS(휴가대장!$F$5:$F$504,휴가대장!$B$5:$B$504,$A10,휴가대장!$E$5:$E$504,"연차",휴가대장!$D$5:$D$504,">="&$B$3,휴가대장!$D$5:$D$504,"<="&EOMONTH($B$3,0)))
A11: =IF(직원명부!A11="","",직원명부!A11) | B11: =IF(직원명부!B11="","",직원명부!B11) | C11: =IF(직원명부!F11="","",직원명부!F11) | D11: =IF($A11="","",COUNTIFS(근태기록!$C$5:$C$2004,$A11,근태기록!$A$5:$A$2004,">="&$B$3,근태기록!$A$5:$A$2004,"<="&EOMONTH($B$3,0),근태기록!$H$5:$H$2004,">0")) | E11: =IF($A11="","",SUMIFS(근태기록!$H$5:$H$2004,근태기록!$C$5:$C$2004,$A11,근태기록!$A$5:$A$2004,">="&$B$3,근태기록!$A$5:$A$2004,"<="&EOMONTH($B$3,0))) | F11: =IF($A11="","",SUMIFS(근태기록!$I$5:$I$2004,근태기록!$C$5:$C$2004,$A11,근태기록!$A$5:$A$2004,">="&$B$3,근태기록!$A$5:$A$2004,"<="&EOMONTH($B$3,0))) | G11: =IF($A11="","",COUNTIFS(근태기록!$C$5:$C$2004,$A11,근태기록!$A$5:$A$2004,">="&$B$3,근태기록!$A$5:$A$2004,"<="&EOMONTH($B$3,0),근태기록!$L$5:$L$2004,"지각")) | H11: =IF($A11="","",COUNTIFS(근태기록!$C$5:$C$2004,$A11,근태기록!$A$5:$A$2004,">="&$B$3,근태기록!$A$5:$A$2004,"<="&EOMONTH($B$3,0),근태기록!$L$5:$L$2004,"조퇴")) | I11: =IF($A11="","",COUNTIFS(근태기록!$C$5:$C$2004,$A11,근태기록!$A$5:$A$2004,">="&$B$3,근태기록!$A$5:$A$2004,"<="&EOMONTH($B$3,0),근태기록!$L$5:$L$2004,"결근")) | J11: =IF($A11="","",SUMIFS(휴가대장!$F$5:$F$504,휴가대장!$B$5:$B$504,$A11,휴가대장!$E$5:$E$504,"연차",휴가대장!$D$5:$D$504,">="&$B$3,휴가대장!$D$5:$D$504,"<="&EOMONTH($B$3,0))) | K11: =IF($A11="","",SUMIFS(휴가대장!$F$5:$F$504,휴가대장!$B$5:$B$504,$A11,휴가대장!$D$5:$D$504,">="&$B$3,휴가대장!$D$5:$D$504,"<="&EOMONTH($B$3,0))-SUMIFS(휴가대장!$F$5:$F$504,휴가대장!$B$5:$B$504,$A11,휴가대장!$E$5:$E$504,"연차",휴가대장!$D$5:$D$504,">="&$B$3,휴가대장!$D$5:$D$504,"<="&EOMONTH($B$3,0)))
A12: =IF(직원명부!A12="","",직원명부!A12) | B12: =IF(직원명부!B12="","",직원명부!B12) | C12: =IF(직원명부!F12="","",직원명부!F12) | D12: =IF($A12="","",COUNTIFS(근태기록!$C$5:$C$2004,$A12,근태기록!$A$5:$A$2004,">="&$B$3,근태기록!$A$5:$A$2004,"<="&EOMONTH($B$3,0),근태기록!$H$5:$H$2004,">0")) | E12: =IF($A12="","",SUMIFS(근태기록!$H$5:$H$2004,근태기록!$C$5:$C$2004,$A12,근태기록!$A$5:$A$2004,">="&$B$3,근태기록!$A$5:$A$2004,"<="&EOMONTH($B$3,0))) | F12: =IF($A12="","",SUMIFS(근태기록!$I$5:$I$2004,근태기록!$C$5:$C$2004,$A12,근태기록!$A$5:$A$2004,">="&$B$3,근태기록!$A$5:$A$2004,"<="&EOMONTH($B$3,0))) | G12: =IF($A12="","",COUNTIFS(근태기록!$C$5:$C$2004,$A12,근태기록!$A$5:$A$2004,">="&$B$3,근태기록!$A$5:$A$2004,"<="&EOMONTH($B$3,0),근태기록!$L$5:$L$2004,"지각")) | H12: =IF($A12="","",COUNTIFS(근태기록!$C$5:$C$2004,$A12,근태기록!$A$5:$A$2004,">="&$B$3,근태기록!$A$5:$A$2004,"<="&EOMONTH($B$3,0),근태기록!$L$5:$L$2004,"조퇴")) | I12: =IF($A12="","",COUNTIFS(근태기록!$C$5:$C$2004,$A12,근태기록!$A$5:$A$2004,">="&$B$3,근태기록!$A$5:$A$2004,"<="&EOMONTH($B$3,0),근태기록!$L$5:$L$2004,"결근")) | J12: =IF($A12="","",SUMIFS(휴가대장!$F$5:$F$504,휴가대장!$B$5:$B$504,$A12,휴가대장!$E$5:$E$504,"연차",휴가대장!$D$5:$D$504,">="&$B$3,휴가대장!$D$5:$D$504,"<="&EOMONTH($B$3,0))) | K12: =IF($A12="","",SUMIFS(휴가대장!$F$5:$F$504,휴가대장!$B$5:$B$504,$A12,휴가대장!$D$5:$D$504,">="&$B$3,휴가대장!$D$5:$D$504,"<="&EOMONTH($B$3,0))-SUMIFS(휴가대장!$F$5:$F$504,휴가대장!$B$5:$B$504,$A12,휴가대장!$E$5:$E$504,"연차",휴가대장!$D$5:$D$504,">="&$B$3,휴가대장!$D$5:$D$504,"<="&EOMONTH($B$3,0)))
A13: =IF(직원명부!A13="","",직원명부!A13) | B13: =IF(직원명부!B13="","",직원명부!B13) | C13: =IF(직원명부!F13="","",직원명부!F13) | D13: =IF($A13="","",COUNTIFS(근태기록!$C$5:$C$2004,$A13,근태기록!$A$5:$A$2004,">="&$B$3,근태기록!$A$5:$A$2004,"<="&EOMONTH($B$3,0),근태기록!$H$5:$H$2004,">0")) | E13: =IF($A13="","",SUMIFS(근태기록!$H$5:$H$2004,근태기록!$C$5:$C$2004,$A13,근태기록!$A$5:$A$2004,">="&$B$3,근태기록!$A$5:$A$2004,"<="&EOMONTH($B$3,0))) | F13: =IF($A13="","",SUMIFS(근태기록!$I$5:$I$2004,근태기록!$C$5:$C$2004,$A13,근태기록!$A$5:$A$2004,">="&$B$3,근태기록!$A$5:$A$2004,"<="&EOMONTH($B$3,0))) | G13: =IF($A13="","",COUNTIFS(근태기록!$C$5:$C$2004,$A13,근태기록!$A$5:$A$2004,">="&$B$3,근태기록!$A$5:$A$2004,"<="&EOMONTH($B$3,0),근태기록!$L$5:$L$2004,"지각")) | H13: =IF($A13="","",COUNTIFS(근태기록!$C$5:$C$2004,$A13,근태기록!$A$5:$A$2004,">="&$B$3,근태기록!$A$5:$A$2004,"<="&EOMONTH($B$3,0),근태기록!$L$5:$L$2004,"조퇴")) | I13: =IF($A13="","",COUNTIFS(근태기록!$C$5:$C$2004,$A13,근태기록!$A$5:$A$2004,">="&$B$3,근태기록!$A$5:$A$2004,"<="&EOMONTH($B$3,0),근태기록!$L$5:$L$2004,"결근")) | J13: =IF($A13="","",SUMIFS(휴가대장!$F$5:$F$504,휴가대장!$B$5:$B$504,$A13,휴가대장!$E$5:$E$504,"연차",휴가대장!$D$5:$D$504,">="&$B$3,휴가대장!$D$5:$D$504,"<="&EOMONTH($B$3,0))) | K13: =IF($A13="","",SUMIFS(휴가대장!$F$5:$F$504,휴가대장!$B$5:$B$504,$A13,휴가대장!$D$5:$D$504,">="&$B$3,휴가대장!$D$5:$D$504,"<="&EOMONTH($B$3,0))-SUMIFS(휴가대장!$F$5:$F$504,휴가대장!$B$5:$B$504,$A13,휴가대장!$E$5:$E$504,"연차",휴가대장!$D$5:$D$504,">="&$B$3,휴가대장!$D$5:$D$504,"<="&EOMONTH($B$3,0)))
A14: =IF(직원명부!A14="","",직원명부!A14) | B14: =IF(직원명부!B14="","",직원명부!B14) | C14: =IF(직원명부!F14="","",직원명부!F14) | D14: =IF($A14="","",COUNTIFS(근태기록!$C$5:$C$2004,$A14,근태기록!$A$5:$A$2004,">="&$B$3,근태기록!$A$5:$A$2004,"<="&EOMONTH($B$3,0),근태기록!$H$5:$H$2004,">0")) | E14: =IF($A14="","",SUMIFS(근태기록!$H$5:$H$2004,근태기록!$C$5:$C$2004,$A14,근태기록!$A$5:$A$2004,">="&$B$3,근태기록!$A$5:$A$2004,"<="&EOMONTH($B$3,0))) | F14: =IF($A14="","",SUMIFS(근태기록!$I$5:$I$2004,근태기록!$C$5:$C$2004,$A14,근태기록!$A$5:$A$2004,">="&$B$3,근태기록!$A$5:$A$2004,"<="&EOMONTH($B$3,0))) | G14: =IF($A14="","",COUNTIFS(근태기록!$C$5:$C$2004,$A14,근태기록!$A$5:$A$2004,">="&$B$3,근태기록!$A$5:$A$2004,"<="&EOMONTH($B$3,0),근태기록!$L$5:$L$2004,"지각")) | H14: =IF($A14="","",COUNTIFS(근태기록!$C$5:$C$2004,$A14,근태기록!$A$5:$A$2004,">="&$B$3,근태기록!$A$5:$A$2004,"<="&EOMONTH($B$3,0),근태기록!$L$5:$L$2004,"조퇴")) | I14: =IF($A14="","",COUNTIFS(근태기록!$C$5:$C$2004,$A14,근태기록!$A$5:$A$2004,">="&$B$3,근태기록!$A$5:$A$2004,"<="&EOMONTH($B$3,0),근태기록!$L$5:$L$2004,"결근")) | J14: =IF($A14="","",SUMIFS(휴가대장!$F$5:$F$504,휴가대장!$B$5:$B$504,$A14,휴가대장!$E$5:$E$504,"연차",휴가대장!$D$5:$D$504,">="&$B$3,휴가대장!$D$5:$D$504,"<="&EOMONTH($B$3,0))) | K14: =IF($A14="","",SUMIFS(휴가대장!$F$5:$F$504,휴가대장!$B$5:$B$504,$A14,휴가대장!$D$5:$D$504,">="&$B$3,휴가대장!$D$5:$D$504,"<="&EOMONTH($B$3,0))-SUMIFS(휴가대장!$F$5:$F$504,휴가대장!$B$5:$B$504,$A14,휴가대장!$E$5:$E$504,"연차",휴가대장!$D$5:$D$504,">="&$B$3,휴가대장!$D$5:$D$504,"<="&EOMONTH($B$3,0)))
A15: =IF(직원명부!A15="","",직원명부!A15) | B15: =IF(직원명부!B15="","",직원명부!B15) | C15: =IF(직원명부!F15="","",직원명부!F15) | D15: =IF($A15="","",COUNTIFS(근태기록!$C$5:$C$2004,$A15,근태기록!$A$5:$A$2004,">="&$B$3,근태기록!$A$5:$A$2004,"<="&EOMONTH($B$3,0),근태기록!$H$5:$H$2004,">0")) | E15: =IF($A15="","",SUMIFS(근태기록!$H$5:$H$2004,근태기록!$C$5:$C$2004,$A15,근태기록!$A$5:$A$2004,">="&$B$3,근태기록!$A$5:$A$2004,"<="&EOMONTH($B$3,0))) | F15: =IF($A15="","",SUMIFS(근태기록!$I$5:$I$2004,근태기록!$C$5:$C$2004,$A15,근태기록!$A$5:$A$2004,">="&$B$3,근태기록!$A$5:$A$2004,"<="&EOMONTH($B$3,0))) | G15: =IF($A15="","",COUNTIFS(근태기록!$C$5:$C$2004,$A15,근태기록!$A$5:$A$2004,">="&$B$3,근태기록!$A$5:$A$2004,"<="&EOMONTH($B$3,0),근태기록!$L$5:$L$2004,"지각")) | H15: =IF($A15="","",COUNTIFS(근태기록!$C$5:$C$2004,$A15,근태기록!$A$5:$A$2004,">="&$B$3,근태기록!$A$5:$A$2004,"<="&EOMONTH($B$3,0),근태기록!$L$5:$L$2004,"조퇴")) | I15: =IF($A15="","",COUNTIFS(근태기록!$C$5:$C$2004,$A15,근태기록!$A$5:$A$2004,">="&$B$3,근태기록!$A$5:$A$2004,"<="&EOMONTH($B$3,0),근태기록!$L$5:$L$2004,"결근")) | J15: =IF($A15="","",SUMIFS(휴가대장!$F$5:$F$504,휴가대장!$B$5:$B$504,$A15,휴가대장!$E$5:$E$504,"연차",휴가대장!$D$5:$D$504,">="&$B$3,휴가대장!$D$5:$D$504,"<="&EOMONTH($B$3,0))) | K15: =IF($A15="","",SUMIFS(휴가대장!$F$5:$F$504,휴가대장!$B$5:$B$504,$A15,휴가대장!$D$5:$D$504,">="&$B$3,휴가대장!$D$5:$D$504,"<="&EOMONTH($B$3,0))-SUMIFS(휴가대장!$F$5:$F$504,휴가대장!$B$5:$B$504,$A15,휴가대장!$E$5:$E$504,"연차",휴가대장!$D$5:$D$504,">="&$B$3,휴가대장!$D$5:$D$504,"<="&EOMONTH($B$3,0)))
A16: =IF(직원명부!A16="","",직원명부!A16) | B16: =IF(직원명부!B16="","",직원명부!B16) | C16: =IF(직원명부!F16="","",직원명부!F16) | D16: =IF($A16="","",COUNTIFS(근태기록!$C$5:$C$2004,$A16,근태기록!$A$5:$A$2004,">="&$B$3,근태기록!$A$5:$A$2004,"<="&EOMONTH($B$3,0),근태기록!$H$5:$H$2004,">0")) | E16: =IF($A16="","",SUMIFS(근태기록!$H$5:$H$2004,근태기록!$C$5:$C$2004,$A16,근태기록!$A$5:$A$2004,">="&$B$3,근태기록!$A$5:$A$2004,"<="&EOMONTH($B$3,0))) | F16: =IF($A16="","",SUMIFS(근태기록!$I$5:$I$2004,근태기록!$C$5:$C$2004,$A16,근태기록!$A$5:$A$2004,">="&$B$3,근태기록!$A$5:$A$2004,"<="&EOMONTH($B$3,0))) | G16: =IF($A16="","",COUNTIFS(근태기록!$C$5:$C$2004,$A16,근태기록!$A$5:$A$2004,">="&$B$3,근태기록!$A$5:$A$2004,"<="&EOMONTH($B$3,0),근태기록!$L$5:$L$2004,"지각")) | H16: =IF($A16="","",COUNTIFS(근태기록!$C$5:$C$2004,$A16,근태기록!$A$5:$A$2004,">="&$B$3,근태기록!$A$5:$A$2004,"<="&EOMONTH($B$3,0),근태기록!$L$5:$L$2004,"조퇴")) | I16: =IF($A16="","",COUNTIFS(근태기록!$C$5:$C$2004,$A16,근태기록!$A$5:$A$2004,">="&$B$3,근태기록!$A$5:$A$2004,"<="&EOMONTH($B$3,0),근태기록!$L$5:$L$2004,"결근")) | J16: =IF($A16="","",SUMIFS(휴가대장!$F$5:$F$504,휴가대장!$B$5:$B$504,$A16,휴가대장!$E$5:$E$504,"연차",휴가대장!$D$5:$D$504,">="&$B$3,휴가대장!$D$5:$D$504,"<="&EOMONTH($B$3,0))) | K16: =IF($A16="","",SUMIFS(휴가대장!$F$5:$F$504,휴가대장!$B$5:$B$504,$A16,휴가대장!$D$5:$D$504,">="&$B$3,휴가대장!$D$5:$D$504,"<="&EOMONTH($B$3,0))-SUMIFS(휴가대장!$F$5:$F$504,휴가대장!$B$5:$B$504,$A16,휴가대장!$E$5:$E$504,"연차",휴가대장!$D$5:$D$504,">="&$B$3,휴가대장!$D$5:$D$504,"<="&EOMONTH($B$3,0)))
... A24: =IF(직원명부!A24="","",직원명부!A24) | B24: =IF(직원명부!B24="","",직원명부!B24) | C24: =IF(직원명부!F24="","",직원명부!F24) | D24: =IF($A24="","",COUNTIFS(근태기록!$C$5:$C$2004,$A24,근태기록!$A$5:$A$2004,">="&$B$3,근태기록!$A$5:$A$2004,"<="&EOMONTH($B$3,0),근태기록!$H$5:$H$2004,">0")) | E24: =IF($A24="","",SUMIFS(근태기록!$H$5:$H$2004,근태기록!$C$5:$C$2004,$A24,근태기록!$A$5:$A$2004,">="&$B$3,근태기록!$A$5:$A$2004,"<="&EOMONTH($B$3,0))) | F24: =IF($A24="","",SUMIFS(근태기록!$I$5:$I$2004,근태기록!$C$5:$C$2004,$A24,근태기록!$A$5:$A$2004,">="&$B$3,근태기록!$A$5:$A$2004,"<="&EOMONTH($B$3,0))) | G24: =IF($A24="","",COUNTIFS(근태기록!$C$5:$C$2004,$A24,근태기록!$A$5:$A$2004,">="&$B$3,근태기록!$A$5:$A$2004,"<="&EOMONTH($B$3,0),근태기록!$L$5:$L$2004,"지각")) | H24: =IF($A24="","",COUNTIFS(근태기록!$C$5:$C$2004,$A24,근태기록!$A$5:$A$2004,">="&$B$3,근태기록!$A$5:$A$2004,"<="&EOMONTH($B$3,0),근태기록!$L$5:$L$2004,"조퇴")) | I24: =IF($A24="","",COUNTIFS(근태기록!$C$5:$C$2004,$A24,근태기록!$A$5:$A$2004,">="&$B$3,근태기록!$A$5:$A$2004,"<="&EOMONTH($B$3,0),근태기록!$L$5:$L$2004,"결근")) | J24: =IF($A24="","",SUMIFS(휴가대장!$F$5:$F$504,휴가대장!$B$5:$B$504,$A24,휴가대장!$E$5:$E$504,"연차",휴가대장!$D$5:$D$504,">="&$B$3,휴가대장!$D$5:$D$504,"<="&EOMONTH($B$3,0))) | K24: =IF($A24="","",SUMIFS(휴가대장!$F$5:$F$504,휴가대장!$B$5:$B$504,$A24,휴가대장!$D$5:$D$504,">="&$B$3,휴가대장!$D$5:$D$504,"<="&EOMONTH($B$3,0))-SUMIFS(휴가대장!$F$5:$F$504,휴가대장!$B$5:$B$504,$A24,휴가대장!$E$5:$E$504,"연차",휴가대장!$D$5:$D$504,">="&$B$3,휴가대장!$D$5:$D$504,"<="&EOMONTH($B$3,0)))
A26: · 「근무일수」는 근태기록에 출근·퇴근이 모두 적혀 근무시간이 0보다 큰 날의 수입니다.
A27: · 「기타휴가」는 연차를 뺀 나머지(경조·병가·공가·출산·육아 등) 전부의 합계입니다.

Sheet 프로젝트집계
A1: 프로젝트집계
A2: 근태기록의 「프로젝트」 칸을 모아 투입시간을 집계합니다. 다음 견적의 근거가 됩니다.
A3: 조회 기간 | B3: 46023 | C3: 46387 | D3: ← 시작일과 종료일. 이 기간에 기록된 근무시간만 집계합니다.
A4: 프로젝트 | B4: 총 근무시간 | C4: 연장시간 | D4: 근무일수 | E4: 인건비 환산 | F4: 비고
B5: =IF($A5="","",SUMIFS(근태기록!$H$5:$H$2004,근태기록!$M$5:$M$2004,$A5,근태기록!$A$5:$A$2004,">="&$B$3,근태기록!$A$5:$A$2004,"<="&$C$3)) | C5: =IF($A5="","",SUMIFS(근태기록!$I$5:$I$2004,근태기록!$M$5:$M$2004,$A5,근태기록!$A$5:$A$2004,">="&$B$3,근태기록!$A$5:$A$2004,"<="&$C$3)) | D5: =IF($A5="","",COUNTIFS(근태기록!$M$5:$M$2004,$A5,근태기록!$A$5:$A$2004,">="&$B$3,근태기록!$A$5:$A$2004,"<="&$C$3,근태기록!$H$5:$H$2004,">0")) | E5: =IF(OR($A5="",$B$36=""),"",ROUND(B5*$B$36,0))
B6: =IF($A6="","",SUMIFS(근태기록!$H$5:$H$2004,근태기록!$M$5:$M$2004,$A6,근태기록!$A$5:$A$2004,">="&$B$3,근태기록!$A$5:$A$2004,"<="&$C$3)) | C6: =IF($A6="","",SUMIFS(근태기록!$I$5:$I$2004,근태기록!$M$5:$M$2004,$A6,근태기록!$A$5:$A$2004,">="&$B$3,근태기록!$A$5:$A$2004,"<="&$C$3)) | D6: =IF($A6="","",COUNTIFS(근태기록!$M$5:$M$2004,$A6,근태기록!$A$5:$A$2004,">="&$B$3,근태기록!$A$5:$A$2004,"<="&$C$3,근태기록!$H$5:$H$2004,">0")) | E6: =IF(OR($A6="",$B$36=""),"",ROUND(B6*$B$36,0))
B7: =IF($A7="","",SUMIFS(근태기록!$H$5:$H$2004,근태기록!$M$5:$M$2004,$A7,근태기록!$A$5:$A$2004,">="&$B$3,근태기록!$A$5:$A$2004,"<="&$C$3)) | C7: =IF($A7="","",SUMIFS(근태기록!$I$5:$I$2004,근태기록!$M$5:$M$2004,$A7,근태기록!$A$5:$A$2004,">="&$B$3,근태기록!$A$5:$A$2004,"<="&$C$3)) | D7: =IF($A7="","",COUNTIFS(근태기록!$M$5:$M$2004,$A7,근태기록!$A$5:$A$2004,">="&$B$3,근태기록!$A$5:$A$2004,"<="&$C$3,근태기록!$H$5:$H$2004,">0")) | E7: =IF(OR($A7="",$B$36=""),"",ROUND(B7*$B$36,0))
B8: =IF($A8="","",SUMIFS(근태기록!$H$5:$H$2004,근태기록!$M$5:$M$2004,$A8,근태기록!$A$5:$A$2004,">="&$B$3,근태기록!$A$5:$A$2004,"<="&$C$3)) | C8: =IF($A8="","",SUMIFS(근태기록!$I$5:$I$2004,근태기록!$M$5:$M$2004,$A8,근태기록!$A$5:$A$2004,">="&$B$3,근태기록!$A$5:$A$2004,"<="&$C$3)) | D8: =IF($A8="","",COUNTIFS(근태기록!$M$5:$M$2004,$A8,근태기록!$A$5:$A$2004,">="&$B$3,근태기록!$A$5:$A$2004,"<="&$C$3,근태기록!$H$5:$H$2004,">0")) | E8: =IF(OR($A8="",$B$36=""),"",ROUND(B8*$B$36,0))
